Workbook

Sheet Accueil
A1: Kit : automatiser ses réseaux sociaux de A à Z
A2: Campus des Bâtisseurs · Connecter • Accompagner • Bâtir
A4: Onglet | B4: À quoi il sert
A5: 2 Charte | B5: Étape 1 · Les 10 rubriques de ta charte, assemblées automatiquement en un texte prêt à coller dans Claude ; tes listes (piliers, réseaux, formats)
A6: 3 Banque idées | B6: Étapes 1 et 2 · Tes idées par pilier avec leur état ; stock et verdict calculés
A7: 4 Calendrier | B7: Étape 2 · Ta semaine type : format, pilier, réseaux ; nombre de posts calculé
A8: 5 Prompts | B8: Toutes les étapes · Les 18 prompts de la formation, prêts à copier
A9: 6 Meilleures heures | B9: Étape 4 · Tes créneaux de publication par réseau, relevés dans Metricool
A10: 7 Suivi stats | B10: Étape 6 · Taux d’engagement et de partage calculés post par post ; synthèse par réseau et par pilier
A11: 8 Plan 14 jours | B11: Toutes les étapes · Ton calendrier d’installation, avec dates, avancement et prochaine action
A12: 9 Checklists | B12: Toutes les étapes · Les checklists des 6 étapes et la checklist finale, avec pourcentage par bloc
A13: 10 Procédure pause | B13: Sécurité · Ta procédure d’urgence en 2 minutes, à imprimer
A15: Mon tableau de bord
A16: Charte remplie | B16: =Charte!C17 -> 0 / 10
A17: Idées « À faire » en stock | B17: ='Banque idées'!J11 -> 2
A18: Verdict du stock d’idées | B18: ='Banque idées'!J14 -> Lance le prompt « 30 idées »
A19: Avancement du plan 14 jours | B19: ='Plan 14 jours'!C22 -> 0
A20: Prochaine action | B20: ='Plan 14 jours'!C23 -> Écrire la charte éditoriale et rassembler 10 exemples de posts
A21: Checklist finale | B21: =Checklists!F12 -> 0
A22: Posts suivis | B22: ='Suivi stats'!Q20 -> 3
A23: Engagement moyen | B23: ='Suivi stats'!Q22 -> 0.05421131
A24: Abonnés gagnés | B24: ='Suivi stats'!Q23 -> 50
A25: Meilleur post (engagement) | B25: ='Suivi stats'!Q25 -> 3 erreurs avant de lancer sa boutique
A27: Comment l’utiliser :
A28: 1. Suis l’ordre des onglets, comme dans la formation et le plan de 14 jours.
A29: 2. Remplis uniquement les cellules jaunes ; les cellules grises se calculent seules.
A30: 3. Les lignes orange sont des exemples : remplace-les par tes données, ou supprime-les.
A31: 4. Commence par l’onglet Charte : ses listes (piliers, réseaux, formats) alimentent les menus déroulants des autres onglets.
A32: 5. Ne stocke jamais de mot de passe ni de clé API dans ce fichier.
A34: Informations vérifiées le 14 octobre 2026 : les menus et offres des outils évoluent, vérifie-les sur les sites officiels.
A36: Campus des Bâtisseurs · campusdesbatisseurs.com · infos@campusdesbatisseurs.com · +221 76 760 22 22
A37: YouTube, TikTok et Facebook : @campusdesbatisseurs

Sheet Charte
A1: Ma charte éditoriale
A2: Étape 1 · Le document le plus important du système. Remplis la colonne C, puis copie la cellule C20 dans les instructions de ton projet Claude.
A3: Légende : cellules jaunes = à remplir · cellules grises = calculées automatiquement · lignes orange = exemples (à remplacer ou supprimer)
A5: N° | B5: Rubrique | C5: Ta réponse | D5: Exemple : Campus des Bâtisseurs
A6: 1 | B6: Qui je suis | D6: Communauté d’apprentissage qui aide à bâtir carrière, entreprise et patrimoine
A7: 2 | B7: Pour qui j’écris | D7: Jeunes actifs, commerçants, entrepreneurs et diaspora d’Afrique francophone
A8: 3 | B8: Ma promesse | D8: Protéger son argent, lancer son business, bâtir un patrimoine
A9: 4 | B9: Mes piliers (3 à 5) | D9: Protéger · Entreprendre · Épargner et investir · Bâtir
A10: 5 | B10: Mon ton | D10: Direct, chaleureux, concret ; tutoiement ; phrases courtes ; exemples en FCFA, Wave, Orange Money
A11: 6 | B11: Ce que je ne dis jamais | D11: Promesses de gains, conseils financiers personnalisés, attaques, politique partisane
A12: 7 | B12: Ma signature et mes appels à l’action | D12: Commenter, partager, écrire GUIDE pour recevoir le guide gratuit
A13: 8 | B13: Mes hashtags | D13: #CampusDesBatisseurs + 2 à 4 hashtags de niche
A14: 9 | B14: Mes couleurs et polices | D14: Bleu nuit #14213D, orange #D9792B ; titres Montserrat, texte Lato
A15: 10 | B15: 10 exemples de mes meilleurs posts | D15: Colle-les tels quels, séparés par une ligne « --- »
B17: Rubriques remplies | C17: =COUNTA(C6:C15)&" / 10" -> 0 / 10
B19: Charte prête à coller dans Claude
B20: Copie cette cellule → | C20: ="CHARTE ÉDITORIALE"&CHAR(10)&B6&" : "&C6&CHAR(10)&B7&" : "&C7&CHAR(10)&B8&" : "&C8&CHAR(10)&B9&" : "&C9&CHAR(10)&B10&" : "&C10&CHAR(10)&B11&" : "&C11&CHAR(10)&B12&" : "&C12&CHAR(10)&B13&" : "&C13&CHAR(10)&B14&" : "&C14&CHAR(10)&B15&" : "&C15 -> CHARTE ÉDITORIALE Qui je suis : Pour qui j’écris : Ma promesse : Mes piliers (3 à 5) : Mon ton : Ce que je ne dis jamais : Ma signature et mes appels à l’action : Mes hashtags : Mes couleurs et polices : 10 exemples de mes meilleurs posts :
B23: Mes listes (utilisées par les autres onglets)
B24: Mes piliers | C24: Réseaux | D24: Formats
B25: Protéger | C25: Facebook | D25: Histoire
B26: Entreprendre | C26: Instagram | D26: Carrousel
B27: Épargner et investir | C27: TikTok | D27: Capture annotée
B28: Bâtir | C28: LinkedIn | D28: Question débat
C29: YouTube | D29: Liste utile
D30: Erreur / bonne pratique
D31: Offre / témoignage
D32: Vidéo courte
B34: Remplace les piliers d’exemple par les tiens : les listes déroulantes se mettent à jour.

Sheet Banque idées
A1: Ma banque d’idées
A2: Étapes 1 et 2 · Une idée par ligne. Le système pioche ici chaque semaine. Objectif : au moins 30 idées « À faire ».
A3: Légende : cellules jaunes = à remplir · cellules grises = calculées automatiquement · lignes orange = exemples (à remplacer ou supprimer)
A5: N° | B5: Pilier | C5: Idée (accroche) | D5: Format conseillé | E5: Source | F5: État | G5: Date prévue | I5: Pilier | J5: À faire | K5: Programmées | L5: Publiées
A6: 1 | B6: Protéger | C6: L’arnaque au faux agent Wave | D6: Capture annotée | E6: Question d’un abonné | F6: À faire | I6: =IF(Charte!B25="","",Charte!B25) -> Protéger | J6: =IF(I6="","",COUNTIFS($B$6:$B$125,I6,$F$6:$F$125,"À faire")) -> 1 | K6: =IF(I6="","",COUNTIFS($B$6:$B$125,I6,$F$6:$F$125,"Programmée")) -> 0 | L6: =IF(I6="","",COUNTIFS($B$6:$B$125,I6,$F$6:$F$125,"Publiée")) -> 0
A7: 2 | B7: Entreprendre | C7: 3 erreurs avant de lancer sa boutique | D7: Carrousel | E7: Commentaire | F7: Programmée | I7: =IF(Charte!B26="","",Charte!B26) -> Entreprendre | J7: =IF(I7="","",COUNTIFS($B$6:$B$125,I7,$F$6:$F$125,"À faire")) -> 0 | K7: =IF(I7="","",COUNTIFS($B$6:$B$125,I7,$F$6:$F$125,"Programmée")) -> 1 | L7: =IF(I7="","",COUNTIFS($B$6:$B$125,I7,$F$6:$F$125,"Publiée")) -> 0
A8: 3 | B8: Épargner et investir | C8: Pourquoi la tontine ne suffit pas | D8: Histoire | E8: Idée perso | F8: Publiée | I8: =IF(Charte!B27="","",Charte!B27) -> Épargner et investir | J8: =IF(I8="","",COUNTIFS($B$6:$B$125,I8,$F$6:$F$125,"À faire")) -> 0 | K8: =IF(I8="","",COUNTIFS($B$6:$B$125,I8,$F$6:$F$125,"Programmée")) -> 0 | L8: =IF(I8="","",COUNTIFS($B$6:$B$125,I8,$F$6:$F$125,"Publiée")) -> 1
A9: 4 | B9: Bâtir | C9: Acheter un terrain sans se faire avoir | D9: Liste utile | E9: Question client | F9: À faire | I9: =IF(Charte!B28="","",Charte!B28) -> Bâtir | J9: =IF(I9="","",COUNTIFS($B$6:$B$125,I9,$F$6:$F$125,"À faire")) -> 1 | K9: =IF(I9="","",COUNTIFS($B$6:$B$125,I9,$F$6:$F$125,"Programmée")) -> 0 | L9: =IF(I9="","",COUNTIFS($B$6:$B$125,I9,$F$6:$F$125,"Publiée")) -> 0
A10: 5 | I10: =IF(Charte!B29="","",Charte!B29) | J10: =IF(I10="","",COUNTIFS($B$6:$B$125,I10,$F$6:$F$125,"À faire")) | K10: =IF(I10="","",COUNTIFS($B$6:$B$125,I10,$F$6:$F$125,"Programmée")) | L10: =IF(I10="","",COUNTIFS($B$6:$B$125,I10,$F$6:$F$125,"Publiée"))
A11: 6 | I11: Total | J11: =COUNTIF($F$6:$F$125,"À faire") -> 2 | K11: =COUNTIF($F$6:$F$125,"Programmée") -> 1 | L11: =COUNTIF($F$6:$F$125,"Publiée") -> 1
A12: 7
A13: 8 | I13: Stock d’idées « À faire » | J13: =J11 -> 2
A14: 9 | I14: Verdict | J14: =IF(J11>=30,"Stock suffisant",IF(J11>=14,"À compléter","Lance le prompt « 30 idées »")) -> Lance le prompt « 30 idées »
A15: 10
A16: 11
A17: 12
A18: 13
A19: 14
A20: 15
A21: 16
A22: 17
A23: 18
A24: 19
A25: 20
A26: 21
... A125: 120

Sheet Calendrier
A1: Ma semaine type
A2: Étape 2 · Un format fixe par jour. Recopie ce planning dans ta charte : le prompt de la semaine le suivra.
A3: Légende : cellules jaunes = à remplir · cellules grises = calculées automatiquement · lignes orange = exemples (à remplacer ou supprimer)
A5: Jour | B5: Format | C5: Pilier | D5: Facebook | E5: Instagram | F5: TikTok | G5: LinkedIn | H5: Notes (heure, appel à l’action…)
A6: Lundi | B6: Histoire | C6: Bâtir | D6: Oui | E6: Oui | F6: Oui | G6: Oui
A7: Mardi | B7: Carrousel | C7: Entreprendre | D7: Oui | E7: Oui | F7: Oui | G7: Oui
A8: Mercredi | B8: Capture annotée | C8: Protéger | D8: Oui | E8: Oui | F8: Oui | G8: Oui
A9: Jeudi | B9: Question débat | C9: Épargner et investir | D9: Oui | E9: Oui | F9: Oui | G9: Oui
A10: Vendredi | B10: Liste utile | C10: Protéger | D10: Oui | E10: Oui | F10: Oui | G10: Oui
A11: Samedi | B11: Erreur / bonne pratique | C11: Entreprendre | D11: Oui | E11: Oui | F11: Oui | G11: Non
A12: Dimanche | B12: Offre / témoignage | C12: Bâtir | D12: Oui | E12: Oui | F12: Oui | G12: Non
A13: Posts / semaine | D13: =COUNTIF(D6:D12,"Oui") -> 7 | E13: =COUNTIF(E6:E12,"Oui") -> 7 | F13: =COUNTIF(F6:F12,"Oui") -> 7 | G13: =COUNTIF(G6:G12,"Oui") -> 5 | H13: =SUM(D13:G13)&" publications par semaine au total" -> 26 publications par semaine au total
A15: Répartition par pilier
B16: =IF(Charte!B25="","",Charte!B25) -> Protéger | C16: =IF(B16="","",COUNTIF($C$6:$C$12,B16)&" jour(s)") -> 2 jour(s)
B17: =IF(Charte!B26="","",Charte!B26) -> Entreprendre | C17: =IF(B17="","",COUNTIF($C$6:$C$12,B17)&" jour(s)") -> 2 jour(s)
B18: =IF(Charte!B27="","",Charte!B27) -> Épargner et investir | C18: =IF(B18="","",COUNTIF($C$6:$C$12,B18)&" jour(s)") -> 1 jour(s)
B19: =IF(Charte!B28="","",Charte!B28) -> Bâtir | C19: =IF(B19="","",COUNTIF($C$6:$C$12,B19)&" jour(s)") -> 2 jour(s)
B20: =IF(Charte!B29="","",Charte!B29) | C20: =IF(B20="","",COUNTIF($C$6:$C$12,B20)&" jour(s)")
A22: Conseil : équilibre tes piliers et garde au plus un post d’offre par semaine pour 5 à 6 posts de valeur.

Sheet Prompts
A1: Tous les prompts de la formation
A2: Prêts à copier. Remplace les [crochets] par tes informations. Les prompts sont en police à chasse fixe pour être copiés facilement.
A5: N° | B5: Prompt | C5: Étape | D5: Quand l’utiliser | E5: Texte à copier
A6: 1 | B6: Test de connexion | C6: 1 | D6: Une fois, après les connecteurs | E6: Liste mes marques Metricool et les réseaux connectés. Ouvre ma charte éditoriale dans Drive et résume-la en 3 lignes.
A7: 2 | B7: Prompt de la semaine | C7: 2 | D7: Chaque semaine (ou dans la tâche) | E7: Tu es mon rédacteur. Suis strictement ma charte éditoriale. Prépare les publications de la semaine du [date du lundi] : - 7 sujets, un par jour, en alternant mes piliers ; - pioche d’abord dans mon fichier « Idées » (Drive, 02_Idees) ; - suis le format de la semaine défini dans ma charte. Pour chaque sujet, écris une version par réseau : - Facebook : 120 à 200 mots, accroche forte, phrases courtes ; - LinkedIn : ton professionnel, 150 à 250 mots, une leçon claire ; - Instagram et TikTok : légende courte + texte de 5 à 8 diapositives si carrousel. Pour chaque post : date | heure | réseau | pilier | texte | hashtags | brief visuel (titre de l’image en 8 mots maximum + description). Enregistre le tout dans un document « Semaine-[numéro] » dans le dossier 03_A_valider de mon Drive.
A8: 3 | B8: Contrôle qualité | C8: 2 | D8: À ajouter à la fin de chaque prompt | E8: Avant de livrer, vérifie chaque post : 1. La première ligne donne-t-elle envie de lire la suite ? 2. Le post respecte-t-il le ton et les interdits de ma charte ? 3. Les chiffres et faits sont-ils exacts et vérifiables ? Sinon, retire-les. 4. Y a-t-il un seul appel à l’action clair ? 5. Le texte respecte-t-il la longueur prévue pour le réseau ? Corrige ce qui ne va pas, puis livre.
A9: 4 | B9: 30 idées pour le mois | C9: 2 | D9: Une fois par mois | E9: À partir de ma charte et des questions reçues en commentaire ce mois-ci, propose 30 idées de posts : 8 par pilier, plus 6 idées d’actualité. Pour chacune : le pilier, l’accroche, le format conseillé. Ajoute-les à mon fichier « Idées ».
A10: 5 | B10: Décliner un post qui a marché | C10: 2 | D10: Après un bon rapport | E10: Ce post a très bien fonctionné : [coller le post]. Écris 5 variantes avec des angles différents (histoire, liste, question, chiffre choc, erreur à éviter), sans répéter les mêmes phrases.
A11: 6 | B11: Transformer un guide en posts | C11: 2 | D11: Pour promouvoir un produit | E11: Voici un chapitre de mon guide : [coller]. Transforme-le en 10 posts de valeur qui donnent envie d’acheter le guide, sans dévoiler tout le contenu. Le 10e post présente l’offre.
A12: 7 | B12: Créer les 5 modèles visuels | C12: 3 | D12: Une seule fois | E12: Crée 5 modèles de visuels pour mes réseaux, sous forme de pages HTML, aux couleurs de ma charte [codes couleurs] et avec mes polices [noms]. Modèles : citation, carrousel (couverture, contenu, appel à l’action), liste, erreur ou bonne pratique, offre. Chaque modèle a des zones de texte remplaçables : {titre}, {texte}, {numero}. Prévois les formats 1080 x 1350 et 1080 x 1920. Enregistre-les dans mon dossier 01_Charte/Modeles.
A13: 8 | B13: Produire les visuels | C13: 3 | D13: Chaque semaine (ou dans la tâche) | E13: Pour chaque post du document « Semaine-[numéro] », crée le visuel décrit dans son brief avec le modèle adapté. Exporte chaque visuel en PNG, nomme-le [date]_[reseau]_[sujet].png et enregistre-le dans 03_A_valider/Semaine-[numéro]/visuels. Vérifie que le texte est lisible et ne déborde pas du cadre ; sinon, raccourcis le titre.
A14: 9 | B14: Tableau pour Canva (création en masse) | C14: 3 | D14: Si tu utilises Canva | E14: Transforme les posts de « Semaine-[numéro] » en tableau CSV avec les colonnes titre ; texte ; numero ; reseau. Titre : 8 mots maximum. Texte : 25 mots maximum.
A15: 10 | B15: Programmation hebdomadaire | C15: 4 | D15: Chaque semaine (ou dans la tâche) | E15: Programme dans Metricool, pour ma marque « [nom de la marque] », tous les posts du document « Semaine-[numéro] », avec leurs visuels. - Utilise les meilleures heures de publication de chaque réseau. - Laisse au moins 5 minutes entre deux publications sur un même réseau. - Crée-les en brouillons à valider, jamais en publication directe. Donne-moi la liste des posts créés : date, heure, réseau. (Rappel : les visuels doivent être importés dans Metricool ou accessibles par un lien public.)
A16: 11 | B16: Semaine en CSV pour Metricool | C16: 4 | D16: Plan B sans connecteur | E16: Transforme les posts de « Semaine-[numéro] » en fichier CSV au format d’import de Metricool [coller ici l’en-tête du modèle CSV téléchargé dans Metricool]. Une ligne par post et par réseau.
A17: 12 | B17: Tâche « Production hebdomadaire » | C17: 5 | D17: Tâche planifiée, dimanche 18 h | E17: Tâche « Production hebdomadaire des réseaux sociaux ». 1. Lis ma charte éditoriale (Drive, 01_Charte) et mon fichier « Idées ». 2. Lis le dernier rapport d’analyse (Drive, 05_Rapports) et tiens compte de ses recommandations. 3. Rédige les 7 posts de la semaine prochaine, une version par réseau, selon le prompt de la semaine et le contrôle qualité. 4. Crée les visuels avec mes modèles. 5. Enregistre textes et visuels dans 03_A_valider/Semaine-[numéro]. 6. Programme chaque post dans Metricool en brouillon à valider, aux meilleures heures, 5 minutes minimum entre deux posts d’un même réseau. 7. Marque les idées utilisées comme « faites » dans le fichier « Idées ». 8. Termine par un résumé : liste des posts, dates, et tout point qui demande mon attention. Ne publie jamais directement : uniquement des brouillons à valider. Si une étape échoue, arrête-toi et explique le problème dans le résumé.
... A23: 18 | B23: SOS · Lancer un produit | C23: Bonus | D23: Lancement | E23: Je lance [produit] le [date]. Prépare une séquence de 10 posts sur 14 jours : 6 posts de valeur liés au sujet, 2 posts de preuve (témoignages réels), 2 posts d’offre. Visuels inclus, brouillons à valider.

Sheet Meilleures heures
A1: Mes meilleures heures de publication
A2: Étape 4 · Relève dans Metricool (Analytique → meilleur moment pour publier) les créneaux où ton audience est la plus active.
A3: Légende : cellules jaunes = à remplir · cellules grises = calculées automatiquement · lignes orange = exemples (à remplacer ou supprimer)
A5: Réseau | B5: Créneau 1 | C5: Créneau 2 | D5: Meilleur jour | E5: Relevé le | F5: Remarques
A6: Facebook
A7: Instagram
A8: TikTok
A9: LinkedIn
A10: YouTube
A11: Autre
A13: Saisis les heures au format 18:30. Mets ces créneaux à jour une fois par trimestre : ton audience évolue.
A14: TikTok : garde au moins 5 minutes d’écart entre deux posts programmés.

Sheet Suivi stats
A1: Le suivi de mes statistiques
A2: Étape 6 · Une ligne par post, à remplir chaque lundi à partir du rapport ou de Metricool. Les taux se calculent seuls.
A3: Légende : cellules jaunes = à remplir · cellules grises = calculées automatiquement · lignes orange = exemples (à remplacer ou supprimer)
P4: Synthèse automatique
A5: Date | B5: Réseau | C5: Pilier | D5: Format | E5: Sujet | F5: Portée | G5: Réactions | H5: Commen-taires | I5: Partages | J5: Enregis-trements | K5: Clics / messages | L5: Nouveaux abonnés | M5: Taux d’engagement | N5: Taux de partage | P5: Par réseau | Q5: Posts | R5: Portée totale | S5: Engagement moyen | T5: Abonnés gagnés
A6: 46300 | B6: Facebook | C6: Protéger | D6: Capture annotée | E6: L’arnaque au faux agent Wave | F6: 5000 | G6: 200 | H6: 30 | I6: 20 | J6: 15 | K6: 12 | L6: 25 | M6: =IF(OR(F6="",F6=0),"",(G6+H6+I6)/F6) -> 0.05 | N6: =IF(OR(F6="",F6=0),"",(I6+J6)/F6) -> 0.007 | P6: =IF(Charte!C25="","",Charte!C25) -> Facebook | Q6: =IF(P6="","",COUNTIFS($B$6:$B$155,P6,$F$6:$F$155,">0")) -> 1 | R6: =IF(P6="","",SUMIFS($F$6:$F$155,$B$6:$B$155,P6)) -> 5000 | S6: =IF(P6="","",IFERROR(AVERAGEIFS($M$6:$M$155,$B$6:$B$155,P6),"")) -> 0.05 | T6: =IF(P6="","",SUMIFS($L$6:$L$155,$B$6:$B$155,P6)) -> 25
A7: 46301 | B7: Instagram | C7: Entreprendre | D7: Carrousel | E7: 3 erreurs avant de lancer sa boutique | F7: 3200 | G7: 180 | H7: 22 | I7: 35 | J7: 60 | K7: 8 | L7: 18 | M7: =IF(OR(F7="",F7=0),"",(G7+H7+I7)/F7) -> 0.0740625 | N7: =IF(OR(F7="",F7=0),"",(I7+J7)/F7) -> 0.0296875 | P7: =IF(Charte!C26="","",Charte!C26) -> Instagram | Q7: =IF(P7="","",COUNTIFS($B$6:$B$155,P7,$F$6:$F$155,">0")) -> 1 | R7: =IF(P7="","",SUMIFS($F$6:$F$155,$B$6:$B$155,P7)) -> 3200 | S7: =IF(P7="","",IFERROR(AVERAGEIFS($M$6:$M$155,$B$6:$B$155,P7),"")) -> 0.0740625 | T7: =IF(P7="","",SUMIFS($L$6:$L$155,$B$6:$B$155,P7)) -> 18
A8: 46303 | B8: LinkedIn | C8: Épargner et investir | D8: Histoire | E8: Pourquoi la tontine ne suffit pas | F8: 2100 | G8: 64 | H8: 11 | I8: 6 | J8: 4 | K8: 5 | L8: 7 | M8: =IF(OR(F8="",F8=0),"",(G8+H8+I8)/F8) -> 0.038571429 | N8: =IF(OR(F8="",F8=0),"",(I8+J8)/F8) -> 0.0047619048 | P8: =IF(Charte!C27="","",Charte!C27) -> TikTok | Q8: =IF(P8="","",COUNTIFS($B$6:$B$155,P8,$F$6:$F$155,">0")) -> 0 | R8: =IF(P8="","",SUMIFS($F$6:$F$155,$B$6:$B$155,P8)) -> 0 | S8: =IF(P8="","",IFERROR(AVERAGEIFS($M$6:$M$155,$B$6:$B$155,P8),"")) | T8: =IF(P8="","",SUMIFS($L$6:$L$155,$B$6:$B$155,P8)) -> 0
M9: =IF(OR(F9="",F9=0),"",(G9+H9+I9)/F9) | N9: =IF(OR(F9="",F9=0),"",(I9+J9)/F9) | P9: =IF(Charte!C28="","",Charte!C28) -> LinkedIn | Q9: =IF(P9="","",COUNTIFS($B$6:$B$155,P9,$F$6:$F$155,">0")) -> 1 | R9: =IF(P9="","",SUMIFS($F$6:$F$155,$B$6:$B$155,P9)) -> 2100 | S9: =IF(P9="","",IFERROR(AVERAGEIFS($M$6:$M$155,$B$6:$B$155,P9),"")) -> 0.038571429 | T9: =IF(P9="","",SUMIFS($L$6:$L$155,$B$6:$B$155,P9)) -> 7
M10: =IF(OR(F10="",F10=0),"",(G10+H10+I10)/F10) | N10: =IF(OR(F10="",F10=0),"",(I10+J10)/F10) | P10: =IF(Charte!C29="","",Charte!C29) -> YouTube | Q10: =IF(P10="","",COUNTIFS($B$6:$B$155,P10,$F$6:$F$155,">0")) -> 0 | R10: =IF(P10="","",SUMIFS($F$6:$F$155,$B$6:$B$155,P10)) -> 0 | S10: =IF(P10="","",IFERROR(AVERAGEIFS($M$6:$M$155,$B$6:$B$155,P10),"")) | T10: =IF(P10="","",SUMIFS($L$6:$L$155,$B$6:$B$155,P10)) -> 0
M11: =IF(OR(F11="",F11=0),"",(G11+H11+I11)/F11) | N11: =IF(OR(F11="",F11=0),"",(I11+J11)/F11)
M12: =IF(OR(F12="",F12=0),"",(G12+H12+I12)/F12) | N12: =IF(OR(F12="",F12=0),"",(I12+J12)/F12) | P12: Par pilier | Q12: Posts | R12: Portée totale | S12: Engagement moyen | T12: Abonnés gagnés
M13: =IF(OR(F13="",F13=0),"",(G13+H13+I13)/F13) | N13: =IF(OR(F13="",F13=0),"",(I13+J13)/F13) | P13: =IF(Charte!B25="","",Charte!B25) -> Protéger | Q13: =IF(P13="","",COUNTIFS($C$6:$C$155,P13,$F$6:$F$155,">0")) -> 1 | R13: =IF(P13="","",SUMIFS($F$6:$F$155,$C$6:$C$155,P13)) -> 5000 | S13: =IF(P13="","",IFERROR(AVERAGEIFS($M$6:$M$155,$C$6:$C$155,P13),"")) -> 0.05 | T13: =IF(P13="","",SUMIFS($L$6:$L$155,$C$6:$C$155,P13)) -> 25
M14: =IF(OR(F14="",F14=0),"",(G14+H14+I14)/F14) | N14: =IF(OR(F14="",F14=0),"",(I14+J14)/F14) | P14: =IF(Charte!B26="","",Charte!B26) -> Entreprendre | Q14: =IF(P14="","",COUNTIFS($C$6:$C$155,P14,$F$6:$F$155,">0")) -> 1 | R14: =IF(P14="","",SUMIFS($F$6:$F$155,$C$6:$C$155,P14)) -> 3200 | S14: =IF(P14="","",IFERROR(AVERAGEIFS($M$6:$M$155,$C$6:$C$155,P14),"")) -> 0.0740625 | T14: =IF(P14="","",SUMIFS($L$6:$L$155,$C$6:$C$155,P14)) -> 18
M15: =IF(OR(F15="",F15=0),"",(G15+H15+I15)/F15) | N15: =IF(OR(F15="",F15=0),"",(I15+J15)/F15) | P15: =IF(Charte!B27="","",Charte!B27) -> Épargner et investir | Q15: =IF(P15="","",COUNTIFS($C$6:$C$155,P15,$F$6:$F$155,">0")) -> 1 | R15: =IF(P15="","",SUMIFS($F$6:$F$155,$C$6:$C$155,P15)) -> 2100 | S15: =IF(P15="","",IFERROR(AVERAGEIFS($M$6:$M$155,$C$6:$C$155,P15),"")) -> 0.038571429 | T15: =IF(P15="","",SUMIFS($L$6:$L$155,$C$6:$C$155,P15)) -> 7
M16: =IF(OR(F16="",F16=0),"",(G16+H16+I16)/F16) | N16: =IF(OR(F16="",F16=0),"",(I16+J16)/F16) | P16: =IF(Charte!B28="","",Charte!B28) -> Bâtir | Q16: =IF(P16="","",COUNTIFS($C$6:$C$155,P16,$F$6:$F$155,">0")) -> 0 | R16: =IF(P16="","",SUMIFS($F$6:$F$155,$C$6:$C$155,P16)) -> 0 | S16: =IF(P16="","",IFERROR(AVERAGEIFS($M$6:$M$155,$C$6:$C$155,P16),"")) | T16: =IF(P16="","",SUMIFS($L$6:$L$155,$C$6:$C$155,P16)) -> 0
M17: =IF(OR(F17="",F17=0),"",(G17+H17+I17)/F17) | N17: =IF(OR(F17="",F17=0),"",(I17+J17)/F17) | P17: =IF(Charte!B29="","",Charte!B29) | Q17: =IF(P17="","",COUNTIFS($C$6:$C$155,P17,$F$6:$F$155,">0")) | R17: =IF(P17="","",SUMIFS($F$6:$F$155,$C$6:$C$155,P17)) | S17: =IF(P17="","",IFERROR(AVERAGEIFS($M$6:$M$155,$C$6:$C$155,P17),"")) | T17: =IF(P17="","",SUMIFS($L$6:$L$155,$C$6:$C$155,P17))
M18: =IF(OR(F18="",F18=0),"",(G18+H18+I18)/F18) | N18: =IF(OR(F18="",F18=0),"",(I18+J18)/F18)
M19: =IF(OR(F19="",F19=0),"",(G19+H19+I19)/F19) | N19: =IF(OR(F19="",F19=0),"",(I19+J19)/F19) | P19: Indicateurs clés | Q19: Valeur
M20: =IF(OR(F20="",F20=0),"",(G20+H20+I20)/F20) | N20: =IF(OR(F20="",F20=0),"",(I20+J20)/F20) | P20: Posts suivis | Q20: =COUNTIF(F6:F155,">0") -> 3
M21: =IF(OR(F21="",F21=0),"",(G21+H21+I21)/F21) | N21: =IF(OR(F21="",F21=0),"",(I21+J21)/F21) | P21: Portée totale | Q21: =SUM(F6:F155) -> 10300
M22: =IF(OR(F22="",F22=0),"",(G22+H22+I22)/F22) | N22: =IF(OR(F22="",F22=0),"",(I22+J22)/F22) | P22: Engagement moyen | Q22: =IFERROR(AVERAGE(M6:M155),"") -> 0.05421131
M23: =IF(OR(F23="",F23=0),"",(G23+H23+I23)/F23) | N23: =IF(OR(F23="",F23=0),"",(I23+J23)/F23) | P23: Abonnés gagnés | Q23: =SUM(L6:L155) -> 50
M24: =IF(OR(F24="",F24=0),"",(G24+H24+I24)/F24) | N24: =IF(OR(F24="",F24=0),"",(I24+J24)/F24) | P24: Clics et messages | Q24: =SUM(K6:K155) -> 25
M25: =IF(OR(F25="",F25=0),"",(G25+H25+I25)/F25) | N25: =IF(OR(F25="",F25=0),"",(I25+J25)/F25) | P25: Meilleur post (engagement) | Q25: =IFERROR(INDEX(E6:E155,MATCH(MAX(M6:M155),M6:M155,0)),"") -> 3 erreurs avant de lancer sa boutique
M26: =IF(OR(F26="",F26=0),"",(G26+H26+I26)/F26) | N26: =IF(OR(F26="",F26=0),"",(I26+J26)/F26) | P26: Meilleur post (partages) | Q26: =IFERROR(INDEX(E6:E155,MATCH(MAX(N6:N155),N6:N155,0)),"") -> 3 erreurs avant de lancer sa boutique
M27: =IF(OR(F27="",F27=0),"",(G27+H27+I27)/F27) | N27: =IF(OR(F27="",F27=0),"",(I27+J27)/F27)
M28: =IF(OR(F28="",F28=0),"",(G28+H28+I28)/F28) | N28: =IF(OR(F28="",F28=0),"",(I28+J28)/F28) | P28: Taux d’engagement = (réactions + commentaires + partages) ÷ portée. Taux de partage = (partages + enregistrements) ÷ portée.
M29: =IF(OR(F29="",F29=0),"",(G29+H29+I29)/F29) | N29: =IF(OR(F29="",F29=0),"",(I29+J29)/F29)
M30: =IF(OR(F30="",F30=0),"",(G30+H30+I30)/F30) | N30: =IF(OR(F30="",F30=0),"",(I30+J30)/F30)
M31: =IF(OR(F31="",F31=0),"",(G31+H31+I31)/F31) | N31: =IF(OR(F31="",F31=0),"",(I31+J31)/F31)
M32: =IF(OR(F32="",F32=0),"",(G32+H32+I32)/F32) | N32: =IF(OR(F32="",F32=0),"",(I32+J32)/F32)
M33: =IF(OR(F33="",F33=0),"",(G33+H33+I33)/F33) | N33: =IF(OR(F33="",F33=0),"",(I33+J33)/F33)
M34: =IF(OR(F34="",F34=0),"",(G34+H34+I34)/F34) | N34: =IF(OR(F34="",F34=0),"",(I34+J34)/F34)
M35: =IF(OR(F35="",F35=0),"",(G35+H35+I35)/F35) | N35: =IF(OR(F35="",F35=0),"",(I35+J35)/F35)
M36: =IF(OR(F36="",F36=0),"",(G36+H36+I36)/F36) | N36: =IF(OR(F36="",F36=0),"",(I36+J36)/F36)
M37: =IF(OR(F37="",F37=0),"",(G37+H37+I37)/F37) | N37: =IF(OR(F37="",F37=0),"",(I37+J37)/F37)
M38: =IF(OR(F38="",F38=0),"",(G38+H38+I38)/F38) | N38: =IF(OR(F38="",F38=0),"",(I38+J38)/F38)
M39: =IF(OR(F39="",F39=0),"",(G39+H39+I39)/F39) | N39: =IF(OR(F39="",F39=0),"",(I39+J39)/F39)
M40: =IF(OR(F40="",F40=0),"",(G40+H40+I40)/F40) | N40: =IF(OR(F40="",F40=0),"",(I40+J40)/F40)
...

Sheet Plan 14 jours
A1: Mon plan de mise en place en 14 jours
A2: Toutes les étapes · Saisis ta date de départ en C4 ; les dates et l’avancement se calculent seuls.
A3: Légende : cellules jaunes = à remplir · cellules grises = calculées automatiquement · lignes orange = exemples (à remplacer ou supprimer)
B4: Date de départ (jour 1) :
A6: Jour | B6: Action | C6: Étape | D6: Date prévue | E6: Fait ? | F6: Notes
A7: 1 | B7: Écrire la charte éditoriale et rassembler 10 exemples de posts | C7: 1 | D7: =IF($C$4="","",$C$4+0) | E7: Non
A8: 2 | B8: Créer le projet Claude, l’arborescence Drive et le fichier « Idées » (30 idées) | C8: 1 | D8: =IF($C$4="","",$C$4+1) | E8: Non
A9: 3 | B9: Créer le compte Metricool, connecter les réseaux, activer la publication automatique | C9: 4 | D9: =IF($C$4="","",$C$4+2) | E9: Non
A10: 4 | B10: Connecter Google Drive et Metricool à Claude ; tester les deux connexions | C10: 1 | D10: =IF($C$4="","",$C$4+3) | E10: Non
A11: 5 | B11: Lancer le prompt de la semaine et relire le résultat | C11: 2 | D11: =IF($C$4="","",$C$4+4) | E11: Non
A12: 6 | B12: Améliorer la charte selon ce qui ne t’a pas plu ; relancer | C12: 2 | D12: =IF($C$4="","",$C$4+5) | E12: Non
A13: 7 | B13: Créer les 5 modèles de visuels | C13: 3 | D13: =IF($C$4="","",$C$4+6) | E13: Non
A14: 8 | B14: Générer les visuels d’une semaine depuis les briefs | C14: 3 | D14: =IF($C$4="","",$C$4+7) | E14: Non
A15: 9 | B15: Programmer un post test depuis Claude, vérifier sa publication | C15: 4 | D15: =IF($C$4="","",$C$4+8) | E15: Non
A16: 10 | B16: Programmer une semaine complète en brouillons à valider ; valider | C16: 4 | D16: =IF($C$4="","",$C$4+9) | E16: Non
A17: 11 | B17: Créer la tâche planifiée « Production hebdomadaire » ; lancement manuel de test | C17: 5 | D17: =IF($C$4="","",$C$4+10) | E17: Non
A18: 12 | B18: Créer la tâche « Rapport hebdomadaire » ; lancement manuel de test | C18: 6 | D18: =IF($C$4="","",$C$4+11) | E18: Non
A19: 13 | B19: Sécuriser : double authentification, révision des accès, procédure « pause » | C19: Sécurité | D19: =IF($C$4="","",$C$4+12) | E19: Non
A20: 14 | B20: Activer les deux tâches à leur horaire ; fixer le rendez-vous de validation du lundi | C20: 5 et 6 | D20: =IF($C$4="","",$C$4+13) | E20: Non
B22: Avancement | C22: =COUNTIF(E7:E20,"Oui")/14 -> 0
B23: Prochaine action | C23: =IFERROR(INDEX(B7:B20,MATCH("Non",E7:E20,0)),"Système en place : bravo !") -> Écrire la charte éditoriale et rassembler 10 exemples de posts
B25: À partir du jour 15 : 15 à 30 minutes de validation par semaine, les réponses aux commentaires, et 15 minutes de bilan par mois.

Sheet Checklists
A1: Mes checklists
A2: Coche « Oui » au fur et à mesure. Ne passe à l’étape suivante que lorsque l’étape en cours est à 100 %.
A3: Légende : cellules jaunes = à remplir · cellules grises = calculées automatiquement · lignes orange = exemples (à remplacer ou supprimer)
A5: Bloc | B5: Point à vérifier | C5: Fait ? | E5: Avancement par bloc | F5: %
A6: Étape 1 · Fondations | B6: Charte écrite, avec 10 exemples de posts | C6: Non | E6: Étape 1 · Fondations | F6: =COUNTIF(C6:C11,"Oui")/6 -> 0
A7: Étape 1 · Fondations | B7: Projet Claude créé avec la charte | C7: Non | E7: Étape 2 · Écriture | F7: =COUNTIF(C12:C17,"Oui")/6 -> 0
A8: Étape 1 · Fondations | B8: Arborescence Drive créée (5 dossiers) | C8: Non | E8: Étape 3 · Visuels | F8: =COUNTIF(C18:C23,"Oui")/6 -> 0
A9: Étape 1 · Fondations | B9: Fichier « Idées » avec au moins 30 idées | C9: Non | E9: Étape 4 · Publication | F9: =COUNTIF(C24:C29,"Oui")/6 -> 0
A10: Étape 1 · Fondations | B10: Google Drive et Metricool connectés à Claude | C10: Non | E10: Étape 5 · Orchestration | F10: =COUNTIF(C30:C35,"Oui")/6 -> 0
A11: Étape 1 · Fondations | B11: Réseaux sociaux connectés dans Metricool | C11: Non | E11: Étape 6 · Analyse | F11: =COUNTIF(C36:C41,"Oui")/6 -> 0
A12: Étape 2 · Écriture | B12: Le prompt de la semaine est enregistré dans mon projet | C12: Non | E12: Checklist finale | F12: =COUNTIF(C42:C50,"Oui")/9 -> 0
A13: Étape 2 · Écriture | B13: Une première semaine a été générée et relue | C13: Non
A14: Étape 2 · Écriture | B14: Le contrôle qualité est ajouté à mes prompts | C14: Non
A15: Étape 2 · Écriture | B15: Le document « Semaine » est rangé dans 03_A_valider | C15: Non
A16: Étape 2 · Écriture | B16: Ma charte a été améliorée après la première relecture | C16: Non
A17: Étape 2 · Écriture | B17: Mon fichier « Idées » est rempli pour le mois | C17: Non
A18: Étape 3 · Visuels | B18: 5 modèles créés à mes couleurs | C18: Non
A19: Étape 3 · Visuels | B19: Formats 1080 × 1350 et 1080 × 1920 prêts | C19: Non
A20: Étape 3 · Visuels | B20: Une semaine de visuels générée depuis les briefs | C20: Non
A21: Étape 3 · Visuels | B21: Visuels rangés dans le dossier de la semaine | C21: Non
A22: Étape 3 · Visuels | B22: Aucun texte qui déborde, tout est lisible sur mobile | C22: Non
A23: Étape 3 · Visuels | B23: Méthode choisie : HTML ou Canva | C23: Non
A24: Étape 4 · Publication | B24: Réseaux connectés, Instagram en compte professionnel | C24: Non
... A50: Checklist finale | B50: Ma procédure « pause » est prête | C50: Non

Sheet Procédure pause
A1: Ma procédure « pause » : urgence en 2 minutes
A2: À imprimer et à garder près de toi. À utiliser en cas d’actualité grave, d’erreur détectée ou de piratage suspecté.
A5: N° | B5: Action | C5: Comment faire
A6: 1 | B6: Mettre la tâche planifiée en pause | C6: Application Claude → Cowork → Scheduled → tâche « Production hebdomadaire » → désactiver. (Routine cloud : claude.ai/code/routines → mettre en pause.)
A7: 2 | B7: Suspendre les posts programmés | C7: Metricool → Planification → posts des 7 prochains jours → repasser en brouillon ou décaler la date. Ou demande à Claude le prompt « Tout mettre en pause » (onglet Prompts).
A8: 3 | B8: Vérifier ce qui est déjà parti | C8: Ouvre chaque réseau et vérifie les posts publiés depuis le début de l’incident ; masque ou supprime manuellement si nécessaire.
A9: 4 | B9: En cas de piratage : changer les mots de passe | C9: Google, Metricool, Claude, Facebook, Instagram, TikTok, LinkedIn, GitHub. Vérifie que la double authentification est active partout.
A10: 5 | B10: En cas de piratage : révoquer les accès | C10: Paramètres de Claude → Connecteurs : déconnecter Drive et Metricool. Révoquer les clés API et les accès des anciens collaborateurs.
A11: 6 | B11: Prévenir ta communauté si nécessaire | C11: Un message court et honnête : ce qui s’est passé, ce que tu as fait, ce que les abonnés doivent ignorer.
A12: 7 | B12: Redémarrer prudemment | C12: Corrige la cause (charte, instructions, accès), lance un test manuel, puis réactive la tâche.
B14: Mes contacts et accès d’urgence
B15: Élément | C15: À compléter
B16: Personne à prévenir (associé, community manager)
B17: Téléphone de cette personne
B18: Où sont stockés mes mots de passe (gestionnaire)
B19: Adresse e-mail de récupération des comptes
B20: Date du dernier test de cette procédure
B22: Ne stocke jamais de mot de passe ou de clé API dans ce fichier.
