Workbook

Sheet Tableau de bord
A1: Tableau de bord du mois
A2: Change le mois dans Paramètres (cellule B8). Seules les commandes « Livrée et payée » comptent dans le chiffre d’affaires.
A3: Cellules jaunes : à remplir · cellules grises : calculées automatiquement (ne pas modifier)
A4: Mois affiché | B4: =Paramètres!$B$17 -> 46296 | C4: =Paramètres!B6 -> Pagnes de Fatou
F5: TOP PRODUITS ET SERVICES DU MOIS
A6: Indicateur | B6: Ce mois | C6: Mois précédent | D6: Évolution | F6: Produit / service | G6: Qté | H6: Chiffre d’affaires | I6: Marge brute | J6: Part du CA
A7: Chiffre d’affaires (FCFA) | B7: =SUMIFS(Ventes!$K$6:$K$505,Ventes!$T$6:$T$505,$B$4,Ventes!$M$6:$M$505,"Livrée et payée") -> 150000 | C7: =SUMIFS(Ventes!$K$6:$K$505,Ventes!$T$6:$T$505,Paramètres!$B$18,Ventes!$M$6:$M$505,"Livrée et payée") -> 64000 | D7: =IF(N(C7)=0,"",B7/C7-1) -> 1.34375 | F7: =IF(Catalogue!B6="","",Catalogue!B6) -> Pagne wax 6 yards | G7: =IF(F7="","",SUMIFS(Ventes!$G$6:$G$505,Ventes!$F$6:$F$505,F7,Ventes!$T$6:$T$505,$B$4,Ventes!$M$6:$M$505,"Livrée et payée")) -> 8 | H7: =IF(F7="","",SUMIFS(Ventes!$K$6:$K$505,Ventes!$F$6:$F$505,F7,Ventes!$T$6:$T$505,$B$4,Ventes!$M$6:$M$505,"Livrée et payée")) -> 80000 | I7: =IF(F7="","",SUMIFS(Ventes!$R$6:$R$505,Ventes!$F$6:$F$505,F7,Ventes!$T$6:$T$505,$B$4)) -> 33600 | J7: =IF(OR(F7="",N($B$7)=0),"",H7/$B$7) -> 0.53333333
A8: Nombre de ventes | B8: =COUNTIFS(Ventes!$T$6:$T$505,$B$4,Ventes!$M$6:$M$505,"Livrée et payée") -> 11 | C8: =COUNTIFS(Ventes!$T$6:$T$505,Paramètres!$B$18,Ventes!$M$6:$M$505,"Livrée et payée") -> 6 | D8: =IF(N(C8)=0,"",B8/C8-1) -> 0.83333333 | F8: =IF(Catalogue!B7="","",Catalogue!B7) -> Foulard assorti | G8: =IF(F8="","",SUMIFS(Ventes!$G$6:$G$505,Ventes!$F$6:$F$505,F8,Ventes!$T$6:$T$505,$B$4,Ventes!$M$6:$M$505,"Livrée et payée")) -> 3 | H8: =IF(F8="","",SUMIFS(Ventes!$K$6:$K$505,Ventes!$F$6:$F$505,F8,Ventes!$T$6:$T$505,$B$4,Ventes!$M$6:$M$505,"Livrée et payée")) -> 10500 | I8: =IF(F8="","",SUMIFS(Ventes!$R$6:$R$505,Ventes!$F$6:$F$505,F8,Ventes!$T$6:$T$505,$B$4)) -> 6450 | J8: =IF(OR(F8="",N($B$7)=0),"",H8/$B$7) -> 0.07
A9: Articles ou prestations vendus | B9: =SUMIFS(Ventes!$G$6:$G$505,Ventes!$T$6:$T$505,$B$4,Ventes!$M$6:$M$505,"Livrée et payée") -> 14 | C9: =SUMIFS(Ventes!$G$6:$G$505,Ventes!$T$6:$T$505,Paramètres!$B$18,Ventes!$M$6:$M$505,"Livrée et payée") -> 7 | D9: =IF(N(C9)=0,"",B9/C9-1) -> 1 | F9: =IF(Catalogue!B8="","",Catalogue!B8) -> Pack 3 pagnes | G9: =IF(F9="","",SUMIFS(Ventes!$G$6:$G$505,Ventes!$F$6:$F$505,F9,Ventes!$T$6:$T$505,$B$4,Ventes!$M$6:$M$505,"Livrée et payée")) -> 2 | H9: =IF(F9="","",SUMIFS(Ventes!$K$6:$K$505,Ventes!$F$6:$F$505,F9,Ventes!$T$6:$T$505,$B$4,Ventes!$M$6:$M$505,"Livrée et payée")) -> 52000 | I9: =IF(F9="","",SUMIFS(Ventes!$R$6:$R$505,Ventes!$F$6:$F$505,F9,Ventes!$T$6:$T$505,$B$4)) -> 24200 | J9: =IF(OR(F9="",N($B$7)=0),"",H9/$B$7) -> 0.34666667
A10: Panier moyen (FCFA) | B10: =IF(N(B8)=0,0,B7/B8) -> 13636.364 | C10: =IF(N(C8)=0,0,C7/C8) -> 10666.667 | D10: =IF(N(C10)=0,"",B10/C10-1) -> 0.27840909 | F10: =IF(Catalogue!B9="","",Catalogue!B9) -> Conseil style à domicile | G10: =IF(F10="","",SUMIFS(Ventes!$G$6:$G$505,Ventes!$F$6:$F$505,F10,Ventes!$T$6:$T$505,$B$4,Ventes!$M$6:$M$505,"Livrée et payée")) -> 1 | H10: =IF(F10="","",SUMIFS(Ventes!$K$6:$K$505,Ventes!$F$6:$F$505,F10,Ventes!$T$6:$T$505,$B$4,Ventes!$M$6:$M$505,"Livrée et payée")) -> 7500 | I10: =IF(F10="","",SUMIFS(Ventes!$R$6:$R$505,Ventes!$F$6:$F$505,F10,Ventes!$T$6:$T$505,$B$4)) -> 5500 | J10: =IF(OR(F10="",N($B$7)=0),"",H10/$B$7) -> 0.05
A11: Commandes annulées ou retournées | B11: =COUNTIFS(Ventes!$T$6:$T$505,$B$4,Ventes!$M$6:$M$505,"Annulée")+COUNTIFS(Ventes!$T$6:$T$505,$B$4,Ventes!$M$6:$M$505,"Retournée") -> 1 | C11: =COUNTIFS(Ventes!$T$6:$T$505,Paramètres!$B$18,Ventes!$M$6:$M$505,"Annulée")+COUNTIFS(Ventes!$T$6:$T$505,Paramètres!$B$18,Ventes!$M$6:$M$505,"Retournée") -> 1 | D11: =IF(N(C11)=0,"",B11/C11-1) -> 0 | F11: =IF(Catalogue!B10="","",Catalogue!B10) | G11: =IF(F11="","",SUMIFS(Ventes!$G$6:$G$505,Ventes!$F$6:$F$505,F11,Ventes!$T$6:$T$505,$B$4,Ventes!$M$6:$M$505,"Livrée et payée")) | H11: =IF(F11="","",SUMIFS(Ventes!$K$6:$K$505,Ventes!$F$6:$F$505,F11,Ventes!$T$6:$T$505,$B$4,Ventes!$M$6:$M$505,"Livrée et payée")) | I11: =IF(F11="","",SUMIFS(Ventes!$R$6:$R$505,Ventes!$F$6:$F$505,F11,Ventes!$T$6:$T$505,$B$4)) | J11: =IF(OR(F11="",N($B$7)=0),"",H11/$B$7)
A12: Taux d’annulation | B12: =IF((B8+B11)=0,0,B11/(B8+B11)) -> 0.083333333 | C12: =IF((C8+C11)=0,0,C11/(C8+C11)) -> 0.14285714 | D12: =(B12-C12)*100 -> -5.952381 | F12: =IF(Catalogue!B11="","",Catalogue!B11) | G12: =IF(F12="","",SUMIFS(Ventes!$G$6:$G$505,Ventes!$F$6:$F$505,F12,Ventes!$T$6:$T$505,$B$4,Ventes!$M$6:$M$505,"Livrée et payée")) | H12: =IF(F12="","",SUMIFS(Ventes!$K$6:$K$505,Ventes!$F$6:$F$505,F12,Ventes!$T$6:$T$505,$B$4,Ventes!$M$6:$M$505,"Livrée et payée")) | I12: =IF(F12="","",SUMIFS(Ventes!$R$6:$R$505,Ventes!$F$6:$F$505,F12,Ventes!$T$6:$T$505,$B$4)) | J12: =IF(OR(F12="",N($B$7)=0),"",H12/$B$7)
A13: Dépenses en publicité (FCFA) | B13: =SUMIFS('Suivi pubs'!$E$6:$E$370,'Suivi pubs'!$N$6:$N$370,$B$4) -> 12000 | C13: =SUMIFS('Suivi pubs'!$E$6:$E$370,'Suivi pubs'!$N$6:$N$370,Paramètres!$B$18) -> 6000 | D13: =IF(N(C13)=0,"",B13/C13-1) -> 1 | F13: =IF(Catalogue!B12="","",Catalogue!B12) | G13: =IF(F13="","",SUMIFS(Ventes!$G$6:$G$505,Ventes!$F$6:$F$505,F13,Ventes!$T$6:$T$505,$B$4,Ventes!$M$6:$M$505,"Livrée et payée")) | H13: =IF(F13="","",SUMIFS(Ventes!$K$6:$K$505,Ventes!$F$6:$F$505,F13,Ventes!$T$6:$T$505,$B$4,Ventes!$M$6:$M$505,"Livrée et payée")) | I13: =IF(F13="","",SUMIFS(Ventes!$R$6:$R$505,Ventes!$F$6:$F$505,F13,Ventes!$T$6:$T$505,$B$4)) | J13: =IF(OR(F13="",N($B$7)=0),"",H13/$B$7)
A14: Messages reçus grâce aux pubs | B14: =SUMIFS('Suivi pubs'!$F$6:$F$370,'Suivi pubs'!$N$6:$N$370,$B$4) -> 49 | C14: =SUMIFS('Suivi pubs'!$F$6:$F$370,'Suivi pubs'!$N$6:$N$370,Paramètres!$B$18) -> 12 | D14: =IF(N(C14)=0,"",B14/C14-1) -> 3.0833333 | F14: =IF(Catalogue!B13="","",Catalogue!B13) | G14: =IF(F14="","",SUMIFS(Ventes!$G$6:$G$505,Ventes!$F$6:$F$505,F14,Ventes!$T$6:$T$505,$B$4,Ventes!$M$6:$M$505,"Livrée et payée")) | H14: =IF(F14="","",SUMIFS(Ventes!$K$6:$K$505,Ventes!$F$6:$F$505,F14,Ventes!$T$6:$T$505,$B$4,Ventes!$M$6:$M$505,"Livrée et payée")) | I14: =IF(F14="","",SUMIFS(Ventes!$R$6:$R$505,Ventes!$F$6:$F$505,F14,Ventes!$T$6:$T$505,$B$4)) | J14: =IF(OR(F14="",N($B$7)=0),"",H14/$B$7)
A15: Ventes notées dans le suivi des pubs | B15: =SUMIFS('Suivi pubs'!$G$6:$G$370,'Suivi pubs'!$N$6:$N$370,$B$4) -> 7 | C15: =SUMIFS('Suivi pubs'!$G$6:$G$370,'Suivi pubs'!$N$6:$N$370,Paramètres!$B$18) -> 1 | D15: =IF(N(C15)=0,"",B15/C15-1) -> 6 | F15: =IF(Catalogue!B14="","",Catalogue!B14) | G15: =IF(F15="","",SUMIFS(Ventes!$G$6:$G$505,Ventes!$F$6:$F$505,F15,Ventes!$T$6:$T$505,$B$4,Ventes!$M$6:$M$505,"Livrée et payée")) | H15: =IF(F15="","",SUMIFS(Ventes!$K$6:$K$505,Ventes!$F$6:$F$505,F15,Ventes!$T$6:$T$505,$B$4,Ventes!$M$6:$M$505,"Livrée et payée")) | I15: =IF(F15="","",SUMIFS(Ventes!$R$6:$R$505,Ventes!$F$6:$F$505,F15,Ventes!$T$6:$T$505,$B$4)) | J15: =IF(OR(F15="",N($B$7)=0),"",H15/$B$7)
A16: Coût par message (FCFA) | B16: =IF(N(B14)=0,0,B13/B14) -> 244.89796 | C16: =IF(N(C14)=0,0,C13/C14) -> 500 | D16: =IF(N(C16)=0,"",B16/C16-1) -> -0.51020408 | F16: =IF(Catalogue!B15="","",Catalogue!B15) | G16: =IF(F16="","",SUMIFS(Ventes!$G$6:$G$505,Ventes!$F$6:$F$505,F16,Ventes!$T$6:$T$505,$B$4,Ventes!$M$6:$M$505,"Livrée et payée")) | H16: =IF(F16="","",SUMIFS(Ventes!$K$6:$K$505,Ventes!$F$6:$F$505,F16,Ventes!$T$6:$T$505,$B$4,Ventes!$M$6:$M$505,"Livrée et payée")) | I16: =IF(F16="","",SUMIFS(Ventes!$R$6:$R$505,Ventes!$F$6:$F$505,F16,Ventes!$T$6:$T$505,$B$4)) | J16: =IF(OR(F16="",N($B$7)=0),"",H16/$B$7)
A17: Taux de conversion des pubs | B17: =IF(N(B14)=0,0,B15/B14) -> 0.14285714 | C17: =IF(N(C14)=0,0,C15/C14) -> 0.083333333 | D17: =(B17-C17)*100 -> 5.952381 | F17: =IF(Catalogue!B16="","",Catalogue!B16) | G17: =IF(F17="","",SUMIFS(Ventes!$G$6:$G$505,Ventes!$F$6:$F$505,F17,Ventes!$T$6:$T$505,$B$4,Ventes!$M$6:$M$505,"Livrée et payée")) | H17: =IF(F17="","",SUMIFS(Ventes!$K$6:$K$505,Ventes!$F$6:$F$505,F17,Ventes!$T$6:$T$505,$B$4,Ventes!$M$6:$M$505,"Livrée et payée")) | I17: =IF(F17="","",SUMIFS(Ventes!$R$6:$R$505,Ventes!$F$6:$F$505,F17,Ventes!$T$6:$T$505,$B$4)) | J17: =IF(OR(F17="",N($B$7)=0),"",H17/$B$7)
A18: Coût par vente en pub (FCFA) | B18: =IF(N(B15)=0,0,B13/B15) -> 1714.2857 | C18: =IF(N(C15)=0,0,C13/C15) -> 6000 | D18: =IF(N(C18)=0,"",B18/C18-1) -> -0.71428571 | F18: =IF(Catalogue!B17="","",Catalogue!B17) | G18: =IF(F18="","",SUMIFS(Ventes!$G$6:$G$505,Ventes!$F$6:$F$505,F18,Ventes!$T$6:$T$505,$B$4,Ventes!$M$6:$M$505,"Livrée et payée")) | H18: =IF(F18="","",SUMIFS(Ventes!$K$6:$K$505,Ventes!$F$6:$F$505,F18,Ventes!$T$6:$T$505,$B$4,Ventes!$M$6:$M$505,"Livrée et payée")) | I18: =IF(F18="","",SUMIFS(Ventes!$R$6:$R$505,Ventes!$F$6:$F$505,F18,Ventes!$T$6:$T$505,$B$4)) | J18: =IF(OR(F18="",N($B$7)=0),"",H18/$B$7)
A19: Marge brute (après produits et livraisons) | B19: =SUMIFS(Ventes!$R$6:$R$505,Ventes!$T$6:$T$505,$B$4) -> 69750 | C19: =SUMIFS(Ventes!$R$6:$R$505,Ventes!$T$6:$T$505,Paramètres!$B$18) -> 30950 | D19: =IF(N(C19)=0,"",B19/C19-1) -> 1.2536349 | F19: =IF(Catalogue!B18="","",Catalogue!B18) | G19: =IF(F19="","",SUMIFS(Ventes!$G$6:$G$505,Ventes!$F$6:$F$505,F19,Ventes!$T$6:$T$505,$B$4,Ventes!$M$6:$M$505,"Livrée et payée")) | H19: =IF(F19="","",SUMIFS(Ventes!$K$6:$K$505,Ventes!$F$6:$F$505,F19,Ventes!$T$6:$T$505,$B$4,Ventes!$M$6:$M$505,"Livrée et payée")) | I19: =IF(F19="","",SUMIFS(Ventes!$R$6:$R$505,Ventes!$F$6:$F$505,F19,Ventes!$T$6:$T$505,$B$4)) | J19: =IF(OR(F19="",N($B$7)=0),"",H19/$B$7)
A20: Autres dépenses (FCFA) | B20: =SUMIFS(Dépenses!$D$6:$D$205,Dépenses!$E$6:$E$205,$B$4) -> 12000 | C20: =SUMIFS(Dépenses!$D$6:$D$205,Dépenses!$E$6:$E$205,Paramètres!$B$18) -> 9000 | D20: =IF(N(C20)=0,"",B20/C20-1) -> 0.33333333 | F20: =IF(Catalogue!B19="","",Catalogue!B19) | G20: =IF(F20="","",SUMIFS(Ventes!$G$6:$G$505,Ventes!$F$6:$F$505,F20,Ventes!$T$6:$T$505,$B$4,Ventes!$M$6:$M$505,"Livrée et payée")) | H20: =IF(F20="","",SUMIFS(Ventes!$K$6:$K$505,Ventes!$F$6:$F$505,F20,Ventes!$T$6:$T$505,$B$4,Ventes!$M$6:$M$505,"Livrée et payée")) | I20: =IF(F20="","",SUMIFS(Ventes!$R$6:$R$505,Ventes!$F$6:$F$505,F20,Ventes!$T$6:$T$505,$B$4)) | J20: =IF(OR(F20="",N($B$7)=0),"",H20/$B$7)
A21: BÉNÉFICE NET (FCFA) | B21: =B19-B13-B20 -> 45750 | C21: =C19-C13-C20 -> 15950 | D21: =IF(N(C21)=0,"",B21/C21-1) -> 1.8683386 | F21: =IF(Catalogue!B20="","",Catalogue!B20) | G21: =IF(F21="","",SUMIFS(Ventes!$G$6:$G$505,Ventes!$F$6:$F$505,F21,Ventes!$T$6:$T$505,$B$4,Ventes!$M$6:$M$505,"Livrée et payée")) | H21: =IF(F21="","",SUMIFS(Ventes!$K$6:$K$505,Ventes!$F$6:$F$505,F21,Ventes!$T$6:$T$505,$B$4,Ventes!$M$6:$M$505,"Livrée et payée")) | I21: =IF(F21="","",SUMIFS(Ventes!$R$6:$R$505,Ventes!$F$6:$F$505,F21,Ventes!$T$6:$T$505,$B$4)) | J21: =IF(OR(F21="",N($B$7)=0),"",H21/$B$7)
A22: Marge nette sur le chiffre d’affaires | B22: =IF(N(B7)=0,0,B21/B7) -> 0.305 | C22: =IF(N(C7)=0,0,C21/C7) -> 0.24921875 | D22: =(B22-C22)*100 -> 5.578125 | F22: =IF(Catalogue!B21="","",Catalogue!B21) | G22: =IF(F22="","",SUMIFS(Ventes!$G$6:$G$505,Ventes!$F$6:$F$505,F22,Ventes!$T$6:$T$505,$B$4,Ventes!$M$6:$M$505,"Livrée et payée")) | H22: =IF(F22="","",SUMIFS(Ventes!$K$6:$K$505,Ventes!$F$6:$F$505,F22,Ventes!$T$6:$T$505,$B$4,Ventes!$M$6:$M$505,"Livrée et payée")) | I22: =IF(F22="","",SUMIFS(Ventes!$R$6:$R$505,Ventes!$F$6:$F$505,F22,Ventes!$T$6:$T$505,$B$4)) | J22: =IF(OR(F22="",N($B$7)=0),"",H22/$B$7)
A23: Ventes à de nouveaux clients | B23: =COUNTIFS(Ventes!$T$6:$T$505,$B$4,Ventes!$M$6:$M$505,"Livrée et payée",Ventes!$U$6:$U$505,"Nouveau") -> 2 | C23: =COUNTIFS(Ventes!$T$6:$T$505,Paramètres!$B$18,Ventes!$M$6:$M$505,"Livrée et payée",Ventes!$U$6:$U$505,"Nouveau") -> 5 | D23: =IF(N(C23)=0,"",B23/C23-1) -> -0.6 | F23: =IF(Catalogue!B22="","",Catalogue!B22) | G23: =IF(F23="","",SUMIFS(Ventes!$G$6:$G$505,Ventes!$F$6:$F$505,F23,Ventes!$T$6:$T$505,$B$4,Ventes!$M$6:$M$505,"Livrée et payée")) | H23: =IF(F23="","",SUMIFS(Ventes!$K$6:$K$505,Ventes!$F$6:$F$505,F23,Ventes!$T$6:$T$505,$B$4,Ventes!$M$6:$M$505,"Livrée et payée")) | I23: =IF(F23="","",SUMIFS(Ventes!$R$6:$R$505,Ventes!$F$6:$F$505,F23,Ventes!$T$6:$T$505,$B$4)) | J23: =IF(OR(F23="",N($B$7)=0),"",H23/$B$7)
A24: Ventes à des clients qui rachètent | B24: =COUNTIFS(Ventes!$T$6:$T$505,$B$4,Ventes!$M$6:$M$505,"Livrée et payée",Ventes!$U$6:$U$505,"Fidèle") -> 9 | C24: =COUNTIFS(Ventes!$T$6:$T$505,Paramètres!$B$18,Ventes!$M$6:$M$505,"Livrée et payée",Ventes!$U$6:$U$505,"Fidèle") -> 1 | D24: =IF(N(C24)=0,"",B24/C24-1) -> 8 | F24: =IF(Catalogue!B23="","",Catalogue!B23) | G24: =IF(F24="","",SUMIFS(Ventes!$G$6:$G$505,Ventes!$F$6:$F$505,F24,Ventes!$T$6:$T$505,$B$4,Ventes!$M$6:$M$505,"Livrée et payée")) | H24: =IF(F24="","",SUMIFS(Ventes!$K$6:$K$505,Ventes!$F$6:$F$505,F24,Ventes!$T$6:$T$505,$B$4,Ventes!$M$6:$M$505,"Livrée et payée")) | I24: =IF(F24="","",SUMIFS(Ventes!$R$6:$R$505,Ventes!$F$6:$F$505,F24,Ventes!$T$6:$T$505,$B$4)) | J24: =IF(OR(F24="",N($B$7)=0),"",H24/$B$7)
A25: Avis demandés après livraison | B25: =IF(N(B8)=0,0,COUNTIFS(Ventes!$T$6:$T$505,$B$4,Ventes!$M$6:$M$505,"Livrée et payée",Ventes!$S$6:$S$505,"Oui")/B8) -> 0.63636364 | C25: =IF(N(C8)=0,0,COUNTIFS(Ventes!$T$6:$T$505,Paramètres!$B$18,Ventes!$M$6:$M$505,"Livrée et payée",Ventes!$S$6:$S$505,"Oui")/C8) -> 0.66666667 | D25: =(B25-C25)*100 -> -3.030303 | F25: =IF(Catalogue!B24="","",Catalogue!B24) | G25: =IF(F25="","",SUMIFS(Ventes!$G$6:$G$505,Ventes!$F$6:$F$505,F25,Ventes!$T$6:$T$505,$B$4,Ventes!$M$6:$M$505,"Livrée et payée")) | H25: =IF(F25="","",SUMIFS(Ventes!$K$6:$K$505,Ventes!$F$6:$F$505,F25,Ventes!$T$6:$T$505,$B$4,Ventes!$M$6:$M$505,"Livrée et payée")) | I25: =IF(F25="","",SUMIFS(Ventes!$R$6:$R$505,Ventes!$F$6:$F$505,F25,Ventes!$T$6:$T$505,$B$4)) | J25: =IF(OR(F25="",N($B$7)=0),"",H25/$B$7)
F26: =IF(Catalogue!B25="","",Catalogue!B25) | G26: =IF(F26="","",SUMIFS(Ventes!$G$6:$G$505,Ventes!$F$6:$F$505,F26,Ventes!$T$6:$T$505,$B$4,Ventes!$M$6:$M$505,"Livrée et payée")) | H26: =IF(F26="","",SUMIFS(Ventes!$K$6:$K$505,Ventes!$F$6:$F$505,F26,Ventes!$T$6:$T$505,$B$4,Ventes!$M$6:$M$505,"Livrée et payée")) | I26: =IF(F26="","",SUMIFS(Ventes!$R$6:$R$505,Ventes!$F$6:$F$505,F26,Ventes!$T$6:$T$505,$B$4)) | J26: =IF(OR(F26="",N($B$7)=0),"",H26/$B$7)
A27: OBJECTIFS DU MOIS
A28: Chiffre d’affaires atteint | B28: =IF(N(Paramètres!B9)=0,"",B7/Paramètres!B9) -> 0.5 | F28: VENTES PAR SOURCE (CE MOIS)
A29: Nombre de ventes atteint | B29: =IF(N(Paramètres!B10)=0,"",B8/Paramètres!B10) -> 0.36666667 | F29: Source | G29: Ventes | H29: Chiffre d’affaires | I29: Part du CA
F30: =IF(Paramètres!H6="","",Paramètres!H6) -> Publicité | G30: =IF(F30="","",COUNTIFS(Ventes!$N$6:$N$505,F30,Ventes!$T$6:$T$505,$B$4,Ventes!$M$6:$M$505,"Livrée et payée")) -> 7 | H30: =IF(F30="","",SUMIFS(Ventes!$K$6:$K$505,Ventes!$N$6:$N$505,F30,Ventes!$T$6:$T$505,$B$4,Ventes!$M$6:$M$505,"Livrée et payée")) -> 86000 | I30: =IF(OR(F30="",N($B$7)=0),"",H30/$B$7) -> 0.57333333
A31: ALERTES | F31: =IF(Paramètres!H7="","",Paramètres!H7) -> Publication gratuite | G31: =IF(F31="","",COUNTIFS(Ventes!$N$6:$N$505,F31,Ventes!$T$6:$T$505,$B$4,Ventes!$M$6:$M$505,"Livrée et payée")) -> 0 | H31: =IF(F31="","",SUMIFS(Ventes!$K$6:$K$505,Ventes!$N$6:$N$505,F31,Ventes!$T$6:$T$505,$B$4,Ventes!$M$6:$M$505,"Livrée et payée")) -> 0 | I31: =IF(OR(F31="",N($B$7)=0),"",H31/$B$7) -> 0
A32: Produits à réapprovisionner | B32: =COUNTIF(Catalogue!$V$6:$V$55,"Réapprovisionner") -> 0 | F32: =IF(Paramètres!H8="","",Paramètres!H8) -> Groupe Facebook | G32: =IF(F32="","",COUNTIFS(Ventes!$N$6:$N$505,F32,Ventes!$T$6:$T$505,$B$4,Ventes!$M$6:$M$505,"Livrée et payée")) -> 0 | H32: =IF(F32="","",SUMIFS(Ventes!$K$6:$K$505,Ventes!$N$6:$N$505,F32,Ventes!$T$6:$T$505,$B$4,Ventes!$M$6:$M$505,"Livrée et payée")) -> 0 | I32: =IF(OR(F32="",N($B$7)=0),"",H32/$B$7) -> 0
A33: Produits vendus à perte ou à marge faible | B33: =COUNTIF(Catalogue!$P$6:$P$55,"Vente à perte")+COUNTIF(Catalogue!$P$6:$P$55,"Marge faible (< x2)") -> 0 | F33: =IF(Paramètres!H9="","",Paramètres!H9) -> Marketplace | G33: =IF(F33="","",COUNTIFS(Ventes!$N$6:$N$505,F33,Ventes!$T$6:$T$505,$B$4,Ventes!$M$6:$M$505,"Livrée et payée")) -> 0 | H33: =IF(F33="","",SUMIFS(Ventes!$K$6:$K$505,Ventes!$N$6:$N$505,F33,Ventes!$T$6:$T$505,$B$4,Ventes!$M$6:$M$505,"Livrée et payée")) -> 0 | I33: =IF(OR(F33="",N($B$7)=0),"",H33/$B$7) -> 0
A34: Pubs à couper | B34: =COUNTIF('Synthèse pubs'!$L$6:$L$35,"Couper") -> 2 | F34: =IF(Paramètres!H10="","",Paramètres!H10) -> Direct vidéo | G34: =IF(F34="","",COUNTIFS(Ventes!$N$6:$N$505,F34,Ventes!$T$6:$T$505,$B$4,Ventes!$M$6:$M$505,"Livrée et payée")) -> 1 | H34: =IF(F34="","",SUMIFS(Ventes!$K$6:$K$505,Ventes!$N$6:$N$505,F34,Ventes!$T$6:$T$505,$B$4,Ventes!$M$6:$M$505,"Livrée et payée")) -> 7500 | I34: =IF(OR(F34="",N($B$7)=0),"",H34/$B$7) -> 0.05
A35: Pubs à augmenter | B35: =COUNTIF('Synthèse pubs'!$L$6:$L$35,"Augmenter*") -> 1 | F35: =IF(Paramètres!H11="","",Paramètres!H11) -> Bouche-à-oreille | G35: =IF(F35="","",COUNTIFS(Ventes!$N$6:$N$505,F35,Ventes!$T$6:$T$505,$B$4,Ventes!$M$6:$M$505,"Livrée et payée")) -> 0 | H35: =IF(F35="","",SUMIFS(Ventes!$K$6:$K$505,Ventes!$N$6:$N$505,F35,Ventes!$T$6:$T$505,$B$4,Ventes!$M$6:$M$505,"Livrée et payée")) -> 0 | I35: =IF(OR(F35="",N($B$7)=0),"",H35/$B$7) -> 0
A36: Clients à relancer (plus de 60 jours) | B36: =COUNTIF(Clients!$I$6:$I$305,"À relancer") -> 0 | F36: =IF(Paramètres!H12="","",Paramètres!H12) -> Client fidèle | G36: =IF(F36="","",COUNTIFS(Ventes!$N$6:$N$505,F36,Ventes!$T$6:$T$505,$B$4,Ventes!$M$6:$M$505,"Livrée et payée")) -> 2 | H36: =IF(F36="","",SUMIFS(Ventes!$K$6:$K$505,Ventes!$N$6:$N$505,F36,Ventes!$T$6:$T$505,$B$4,Ventes!$M$6:$M$505,"Livrée et payée")) -> 46000 | I36: =IF(OR(F36="",N($B$7)=0),"",H36/$B$7) -> 0.30666667
A37: Commandes en attente | B37: =COUNTIF(Ventes!$M$6:$M$505,"En attente") -> 1 | F37: =IF(Paramètres!H13="","",Paramètres!H13) -> Statut WhatsApp | G37: =IF(F37="","",COUNTIFS(Ventes!$N$6:$N$505,F37,Ventes!$T$6:$T$505,$B$4,Ventes!$M$6:$M$505,"Livrée et payée")) -> 1 | H37: =IF(F37="","",SUMIFS(Ventes!$K$6:$K$505,Ventes!$N$6:$N$505,F37,Ventes!$T$6:$T$505,$B$4,Ventes!$M$6:$M$505,"Livrée et payée")) -> 10500 | I37: =IF(OR(F37="",N($B$7)=0),"",H37/$B$7) -> 0.07
F38: =IF(Paramètres!H14="","",Paramètres!H14) | G38: =IF(F38="","",COUNTIFS(Ventes!$N$6:$N$505,F38,Ventes!$T$6:$T$505,$B$4,Ventes!$M$6:$M$505,"Livrée et payée")) | H38: =IF(F38="","",SUMIFS(Ventes!$K$6:$K$505,Ventes!$N$6:$N$505,F38,Ventes!$T$6:$T$505,$B$4,Ventes!$M$6:$M$505,"Livrée et payée")) | I38: =IF(OR(F38="",N($B$7)=0),"",H38/$B$7)
F39: =IF(Paramètres!H15="","",Paramètres!H15) | G39: =IF(F39="","",COUNTIFS(Ventes!$N$6:$N$505,F39,Ventes!$T$6:$T$505,$B$4,Ventes!$M$6:$M$505,"Livrée et payée")) | H39: =IF(F39="","",SUMIFS(Ventes!$K$6:$K$505,Ventes!$N$6:$N$505,F39,Ventes!$T$6:$T$505,$B$4,Ventes!$M$6:$M$505,"Livrée et payée")) | I39: =IF(OR(F39="",N($B$7)=0),"",H39/$B$7)

Sheet Accueil
A1: Outil de pilotage · Vendre sur Facebook, gagner plus
A2: Suivi des ventes, des pubs, des produits et services, des clients et du bénéfice, en un seul fichier.
A3: Cellules jaunes : à remplir · cellules grises : calculées automatiquement (ne pas modifier)
B5: Campus des Bâtisseurs · Connecter • Accompagner • Bâtir
B7: Onglet | C7: À quoi il sert
B8: Paramètres | C8: Ton business, le mois suivi, tes objectifs, tes zones de livraison et les listes de choix. À remplir en premier.
B9: Catalogue | C9: Tes produits et services : coûts, prix, marge réelle, plafond de pub par vente, stock et alertes.
B10: Grille produit | C10: Note un produit avant de le lancer (6 critères du chapitre 2). 9 sur 12 ou plus : à tester.
B11: Calcul marge | C11: Simulateur : vrai bénéfice par vente, prix minimum, et calcul rapide d’une pub (coût par vente, décision).
B12: Suivi pubs | C12: Chaque soir : dépensé, messages, ventes de chaque pub. Coût par message, conversion, coût par vente calculés.
B13: Synthèse pubs | C13: Le bilan cumulé de chaque pub et la décision : augmenter, améliorer ou couper (chapitre 8).
B14: Ventes | C14: Le journal de toutes tes commandes : client, produit, paiement, statut, livraison, marge.
B15: Clients | C15: Ta liste de clients : nombre d’achats, montant total, dernière commande, segment (fidèle, VIP, à relancer).
B16: Dépenses | C16: Les autres frais du business : emballages en gros, transport, internet, livreur, matériel.
B17: Tableau de bord | C17: L’aperçu clair du mois : chiffre d’affaires, bénéfice net, pub, conversion, top produits, alertes.
B18: Bilan annuel | C18: Les 12 mois de l’année côte à côte, avec graphique.
... B20: Page pro | C20: La checklist « page pro » en 20 points, avec ton score.
B22: Mode d’emploi en 5 étapes
B23: 1. Remplis Paramètres (année, mois suivi, objectifs, zones de livraison).
B24: 2. Ajoute tes produits et services dans Catalogue. Vérifie que chaque marge est saine.
B25: 3. Chaque soir, note tes pubs dans Suivi pubs et tes commandes dans Ventes.
B26: 4. Une fois par semaine, regarde Synthèse pubs : augmente, améliore ou coupe chaque pub.
B27: 5. En fin de mois, ouvre Tableau de bord, puis Bilan annuel : tes chiffres décident, pas tes émotions.
B29: Règle de comptage : seules les commandes au statut « Livrée et payée » comptent dans le chiffre d’affaires.
B30: Une commande « Annulée » avec une livraison payée par toi est comptée comme une perte (le livreur a été payé pour rien).
B31: Pour un service, indique ton coût de revient (matériel, déplacement, sous-traitance) et choisis « Service » : le stock est ignoré.
B33: campusdesbatisseurs.com · infos@campusdesbatisseurs.com · +221 76 760 22 22 · @campusdesbatisseurs
B35: FICHIER D’EXEMPLE : les données sont fictives (boutique de pagnes de Fatou). Utilise le fichier vierge pour ton business.

Sheet Paramètres
A1: Paramètres
A2: À remplir en premier. Les listes alimentent les menus déroulants des autres onglets.
A3: Cellules jaunes : à remplir · cellules grises : calculées automatiquement (ne pas modifier)
A5: Paramètre | B5: Valeur | D5: Modes de paiement | F5: Statuts de commande | H5: Sources de la vente | J5: Zones de livraison | K5: Tarif livreur (FCFA) | M5: Catégories de dépenses | O5: Types
A6: Nom du business | B6: Pagnes de Fatou | D6: Wave | F6: En attente | H6: Publicité | J6: Dakar Plateau | K6: 1000 | M6: Emballages en gros | O6: Produit
A7: Année suivie | B7: 2026 | D7: Orange Money | F7: Livrée et payée | H7: Publication gratuite | J7: Dakar banlieue | K7: 1500 | M7: Transport / achats | O7: Service
A8: Mois suivi (1 à 12) | B8: 10 | D8: Free Money | F8: Annulée | H8: Groupe Facebook | J8: Pikine / Guédiawaye | K8: 2000 | M8: Internet et crédit
A9: Objectif de chiffre d’affaires mensuel (FCFA) | B9: 300000 | D9: Espèces à la livraison | F9: Retournée | H9: Marketplace | J9: Rufisque | K9: 2500 | M9: Livreur (forfait)
A10: Objectif de nombre de ventes par mois | B10: 30 | D10: Acompte + solde | H10: Direct vidéo | J10: Thiès | K10: 3000 | M10: Matériel
A11: Seuil « augmenter » : coût par vente < marge × | B11: 0.33333333 | D11: Virement bancaire | H11: Bouche-à-oreille | J11: Autres régions | K11: 3500 | M11: Photos / vidéos
A12: Jours minimum avant de décider (pub) | B12: 3 | H12: Client fidèle | M12: Formation
A13: Repère de conversion faible (messages → ventes) | B13: 0.1 | H13: Statut WhatsApp | M13: Autre
A15: Le seuil 1/3 et les 3 jours viennent de la règle de décision du chapitre 8. Le repère de 10 % de conversion est indicatif.
A17: Mois suivi (calculé) | B17: =DATE(B7,B8,1) -> 46296
A18: Mois précédent (calculé) | B18: =DATE(YEAR(B17),MONTH(B17)-1,1) -> 46266

Sheet Catalogue
A1: Catalogue des produits et services
A2: Coût total avant pub = achat + emballage + livraison payée par toi + frais. Marge avant pub = ton plafond de dépense pub par vente (chapitre 8).
A3: Cellules jaunes : à remplir · cellules grises : calculées automatiquement (ne pas modifier)
A5: Réf. | B5: Nom du produit ou service | C5: Type | D5: Catégorie | E5: Coût d’achat / de revient | F5: Emballage | G5: Livraison payée par toi | H5: Frais divers | I5: Prix de vente | J5: Coût total avant pub | K5: Marge avant pub | L5: Taux de marge | M5: Coef. prix / coût | N5: Plafond pub par vente | O5: Seuil « augmenter » | P5: Verdict prix | Q5: Stock initial | R5: Réappro. | S5: Vendus | T5: Stock restant | U5: Stock mini | V5: Alerte stock
A6: P01 | B6: Pagne wax 6 yards | C6: Produit | D6: Mode | E6: 4000 | F6: 200 | G6: 1500 | H6: 100 | I6: 10000 | J6: =IF(I6="","",N(E6)+N(F6)+N(G6)+N(H6)) -> 5800 | K6: =IF(I6="","",I6-J6) -> 4200 | L6: =IF(OR(I6="",N(I6)=0),"",K6/I6) -> 0.42 | M6: =IF(OR(I6="",N(E6)=0),"",I6/E6) -> 2.5 | N6: =IF(I6="","",MAX(0,K6)) -> 4200 | O6: =IF(I6="","",MAX(0,K6*Paramètres!$B$11)) -> 1400 | P6: =IF(I6="","",IF(K6<=0,"Vente à perte",IF(AND(M6<>"",M6<2),"Marge faible (< x2)","Marge saine"))) -> Marge saine | Q6: 30 | R6: 20 | S6: =IF(B6="","",SUMIFS(Ventes!$G$6:$G$505,Ventes!$F$6:$F$505,B6,Ventes!$M$6:$M$505,"Livrée et payée")) -> 10 | T6: =IF(OR(B6="",C6="Service"),"",N(Q6)+N(R6)-N(S6)) -> 40 | U6: 5 | V6: =IF(OR(B6="",C6="Service",Q6=""),"",IF(T6<=N(U6),"Réapprovisionner","OK")) -> OK
A7: P02 | B7: Foulard assorti | C7: Produit | D7: Accessoires | E7: 1200 | F7: 100 | G7: 0 | H7: 50 | I7: 3500 | J7: =IF(I7="","",N(E7)+N(F7)+N(G7)+N(H7)) -> 1350 | K7: =IF(I7="","",I7-J7) -> 2150 | L7: =IF(OR(I7="",N(I7)=0),"",K7/I7) -> 0.61428571 | M7: =IF(OR(I7="",N(E7)=0),"",I7/E7) -> 2.9166667 | N7: =IF(I7="","",MAX(0,K7)) -> 2150 | O7: =IF(I7="","",MAX(0,K7*Paramètres!$B$11)) -> 716.66667 | P7: =IF(I7="","",IF(K7<=0,"Vente à perte",IF(AND(M7<>"",M7<2),"Marge faible (< x2)","Marge saine"))) -> Marge saine | Q7: 40 | R7: 0 | S7: =IF(B7="","",SUMIFS(Ventes!$G$6:$G$505,Ventes!$F$6:$F$505,B7,Ventes!$M$6:$M$505,"Livrée et payée")) -> 6 | T7: =IF(OR(B7="",C7="Service"),"",N(Q7)+N(R7)-N(S7)) -> 34 | U7: 10 | V7: =IF(OR(B7="",C7="Service",Q7=""),"",IF(T7<=N(U7),"Réapprovisionner","OK")) -> OK
A8: P03 | B8: Pack 3 pagnes | C8: Produit | D8: Mode | E8: 12000 | F8: 300 | G8: 1500 | H8: 100 | I8: 27000 | J8: =IF(I8="","",N(E8)+N(F8)+N(G8)+N(H8)) -> 13900 | K8: =IF(I8="","",I8-J8) -> 13100 | L8: =IF(OR(I8="",N(I8)=0),"",K8/I8) -> 0.48518519 | M8: =IF(OR(I8="",N(E8)=0),"",I8/E8) -> 2.25 | N8: =IF(I8="","",MAX(0,K8)) -> 13100 | O8: =IF(I8="","",MAX(0,K8*Paramètres!$B$11)) -> 4366.6667 | P8: =IF(I8="","",IF(K8<=0,"Vente à perte",IF(AND(M8<>"",M8<2),"Marge faible (< x2)","Marge saine"))) -> Marge saine | Q8: 10 | R8: 0 | S8: =IF(B8="","",SUMIFS(Ventes!$G$6:$G$505,Ventes!$F$6:$F$505,B8,Ventes!$M$6:$M$505,"Livrée et payée")) -> 3 | T8: =IF(OR(B8="",C8="Service"),"",N(Q8)+N(R8)-N(S8)) -> 7 | U8: 3 | V8: =IF(OR(B8="",C8="Service",Q8=""),"",IF(T8<=N(U8),"Réapprovisionner","OK")) -> OK
A9: P04 | B9: Conseil style à domicile | C9: Service | D9: Services | E9: 2000 | F9: 0 | G9: 0 | H9: 0 | I9: 7500 | J9: =IF(I9="","",N(E9)+N(F9)+N(G9)+N(H9)) -> 2000 | K9: =IF(I9="","",I9-J9) -> 5500 | L9: =IF(OR(I9="",N(I9)=0),"",K9/I9) -> 0.73333333 | M9: =IF(OR(I9="",N(E9)=0),"",I9/E9) -> 3.75 | N9: =IF(I9="","",MAX(0,K9)) -> 5500 | O9: =IF(I9="","",MAX(0,K9*Paramètres!$B$11)) -> 1833.3333 | P9: =IF(I9="","",IF(K9<=0,"Vente à perte",IF(AND(M9<>"",M9<2),"Marge faible (< x2)","Marge saine"))) -> Marge saine | S9: =IF(B9="","",SUMIFS(Ventes!$G$6:$G$505,Ventes!$F$6:$F$505,B9,Ventes!$M$6:$M$505,"Livrée et payée")) -> 2 | T9: =IF(OR(B9="",C9="Service"),"",N(Q9)+N(R9)-N(S9)) | V9: =IF(OR(B9="",C9="Service",Q9=""),"",IF(T9<=N(U9),"Réapprovisionner","OK"))
J10: =IF(I10="","",N(E10)+N(F10)+N(G10)+N(H10)) | K10: =IF(I10="","",I10-J10) | L10: =IF(OR(I10="",N(I10)=0),"",K10/I10) | M10: =IF(OR(I10="",N(E10)=0),"",I10/E10) | N10: =IF(I10="","",MAX(0,K10)) | O10: =IF(I10="","",MAX(0,K10*Paramètres!$B$11)) | P10: =IF(I10="","",IF(K10<=0,"Vente à perte",IF(AND(M10<>"",M10<2),"Marge faible (< x2)","Marge saine"))) | S10: =IF(B10="","",SUMIFS(Ventes!$G$6:$G$505,Ventes!$F$6:$F$505,B10,Ventes!$M$6:$M$505,"Livrée et payée")) | T10: =IF(OR(B10="",C10="Service"),"",N(Q10)+N(R10)-N(S10)) | V10: =IF(OR(B10="",C10="Service",Q10=""),"",IF(T10<=N(U10),"Réapprovisionner","OK"))
J11: =IF(I11="","",N(E11)+N(F11)+N(G11)+N(H11)) | K11: =IF(I11="","",I11-J11) | L11: =IF(OR(I11="",N(I11)=0),"",K11/I11) | M11: =IF(OR(I11="",N(E11)=0),"",I11/E11) | N11: =IF(I11="","",MAX(0,K11)) | O11: =IF(I11="","",MAX(0,K11*Paramètres!$B$11)) | P11: =IF(I11="","",IF(K11<=0,"Vente à perte",IF(AND(M11<>"",M11<2),"Marge faible (< x2)","Marge saine"))) | S11: =IF(B11="","",SUMIFS(Ventes!$G$6:$G$505,Ventes!$F$6:$F$505,B11,Ventes!$M$6:$M$505,"Livrée et payée")) | T11: =IF(OR(B11="",C11="Service"),"",N(Q11)+N(R11)-N(S11)) | V11: =IF(OR(B11="",C11="Service",Q11=""),"",IF(T11<=N(U11),"Réapprovisionner","OK"))
J12: =IF(I12="","",N(E12)+N(F12)+N(G12)+N(H12)) | K12: =IF(I12="","",I12-J12) | L12: =IF(OR(I12="",N(I12)=0),"",K12/I12) | M12: =IF(OR(I12="",N(E12)=0),"",I12/E12) | N12: =IF(I12="","",MAX(0,K12)) | O12: =IF(I12="","",MAX(0,K12*Paramètres!$B$11)) | P12: =IF(I12="","",IF(K12<=0,"Vente à perte",IF(AND(M12<>"",M12<2),"Marge faible (< x2)","Marge saine"))) | S12: =IF(B12="","",SUMIFS(Ventes!$G$6:$G$505,Ventes!$F$6:$F$505,B12,Ventes!$M$6:$M$505,"Livrée et payée")) | T12: =IF(OR(B12="",C12="Service"),"",N(Q12)+N(R12)-N(S12)) | V12: =IF(OR(B12="",C12="Service",Q12=""),"",IF(T12<=N(U12),"Réapprovisionner","OK"))
J13: =IF(I13="","",N(E13)+N(F13)+N(G13)+N(H13)) | K13: =IF(I13="","",I13-J13) | L13: =IF(OR(I13="",N(I13)=0),"",K13/I13) | M13: =IF(OR(I13="",N(E13)=0),"",I13/E13) | N13: =IF(I13="","",MAX(0,K13)) | O13: =IF(I13="","",MAX(0,K13*Paramètres!$B$11)) | P13: =IF(I13="","",IF(K13<=0,"Vente à perte",IF(AND(M13<>"",M13<2),"Marge faible (< x2)","Marge saine"))) | S13: =IF(B13="","",SUMIFS(Ventes!$G$6:$G$505,Ventes!$F$6:$F$505,B13,Ventes!$M$6:$M$505,"Livrée et payée")) | T13: =IF(OR(B13="",C13="Service"),"",N(Q13)+N(R13)-N(S13)) | V13: =IF(OR(B13="",C13="Service",Q13=""),"",IF(T13<=N(U13),"Réapprovisionner","OK"))
J14: =IF(I14="","",N(E14)+N(F14)+N(G14)+N(H14)) | K14: =IF(I14="","",I14-J14) | L14: =IF(OR(I14="",N(I14)=0),"",K14/I14) | M14: =IF(OR(I14="",N(E14)=0),"",I14/E14) | N14: =IF(I14="","",MAX(0,K14)) | O14: =IF(I14="","",MAX(0,K14*Paramètres!$B$11)) | P14: =IF(I14="","",IF(K14<=0,"Vente à perte",IF(AND(M14<>"",M14<2),"Marge faible (< x2)","Marge saine"))) | S14: =IF(B14="","",SUMIFS(Ventes!$G$6:$G$505,Ventes!$F$6:$F$505,B14,Ventes!$M$6:$M$505,"Livrée et payée")) | T14: =IF(OR(B14="",C14="Service"),"",N(Q14)+N(R14)-N(S14)) | V14: =IF(OR(B14="",C14="Service",Q14=""),"",IF(T14<=N(U14),"Réapprovisionner","OK"))
J15: =IF(I15="","",N(E15)+N(F15)+N(G15)+N(H15)) | K15: =IF(I15="","",I15-J15) | L15: =IF(OR(I15="",N(I15)=0),"",K15/I15) | M15: =IF(OR(I15="",N(E15)=0),"",I15/E15) | N15: =IF(I15="","",MAX(0,K15)) | O15: =IF(I15="","",MAX(0,K15*Paramètres!$B$11)) | P15: =IF(I15="","",IF(K15<=0,"Vente à perte",IF(AND(M15<>"",M15<2),"Marge faible (< x2)","Marge saine"))) | S15: =IF(B15="","",SUMIFS(Ventes!$G$6:$G$505,Ventes!$F$6:$F$505,B15,Ventes!$M$6:$M$505,"Livrée et payée")) | T15: =IF(OR(B15="",C15="Service"),"",N(Q15)+N(R15)-N(S15)) | V15: =IF(OR(B15="",C15="Service",Q15=""),"",IF(T15<=N(U15),"Réapprovisionner","OK"))
J16: =IF(I16="","",N(E16)+N(F16)+N(G16)+N(H16)) | K16: =IF(I16="","",I16-J16) | L16: =IF(OR(I16="",N(I16)=0),"",K16/I16) | M16: =IF(OR(I16="",N(E16)=0),"",I16/E16) | N16: =IF(I16="","",MAX(0,K16)) | O16: =IF(I16="","",MAX(0,K16*Paramètres!$B$11)) | P16: =IF(I16="","",IF(K16<=0,"Vente à perte",IF(AND(M16<>"",M16<2),"Marge faible (< x2)","Marge saine"))) | S16: =IF(B16="","",SUMIFS(Ventes!$G$6:$G$505,Ventes!$F$6:$F$505,B16,Ventes!$M$6:$M$505,"Livrée et payée")) | T16: =IF(OR(B16="",C16="Service"),"",N(Q16)+N(R16)-N(S16)) | V16: =IF(OR(B16="",C16="Service",Q16=""),"",IF(T16<=N(U16),"Réapprovisionner","OK"))
J17: =IF(I17="","",N(E17)+N(F17)+N(G17)+N(H17)) | K17: =IF(I17="","",I17-J17) | L17: =IF(OR(I17="",N(I17)=0),"",K17/I17) | M17: =IF(OR(I17="",N(E17)=0),"",I17/E17) | N17: =IF(I17="","",MAX(0,K17)) | O17: =IF(I17="","",MAX(0,K17*Paramètres!$B$11)) | P17: =IF(I17="","",IF(K17<=0,"Vente à perte",IF(AND(M17<>"",M17<2),"Marge faible (< x2)","Marge saine"))) | S17: =IF(B17="","",SUMIFS(Ventes!$G$6:$G$505,Ventes!$F$6:$F$505,B17,Ventes!$M$6:$M$505,"Livrée et payée")) | T17: =IF(OR(B17="",C17="Service"),"",N(Q17)+N(R17)-N(S17)) | V17: =IF(OR(B17="",C17="Service",Q17=""),"",IF(T17<=N(U17),"Réapprovisionner","OK"))
J18: =IF(I18="","",N(E18)+N(F18)+N(G18)+N(H18)) | K18: =IF(I18="","",I18-J18) | L18: =IF(OR(I18="",N(I18)=0),"",K18/I18) | M18: =IF(OR(I18="",N(E18)=0),"",I18/E18) | N18: =IF(I18="","",MAX(0,K18)) | O18: =IF(I18="","",MAX(0,K18*Paramètres!$B$11)) | P18: =IF(I18="","",IF(K18<=0,"Vente à perte",IF(AND(M18<>"",M18<2),"Marge faible (< x2)","Marge saine"))) | S18: =IF(B18="","",SUMIFS(Ventes!$G$6:$G$505,Ventes!$F$6:$F$505,B18,Ventes!$M$6:$M$505,"Livrée et payée")) | T18: =IF(OR(B18="",C18="Service"),"",N(Q18)+N(R18)-N(S18)) | V18: =IF(OR(B18="",C18="Service",Q18=""),"",IF(T18<=N(U18),"Réapprovisionner","OK"))
J19: =IF(I19="","",N(E19)+N(F19)+N(G19)+N(H19)) | K19: =IF(I19="","",I19-J19) | L19: =IF(OR(I19="",N(I19)=0),"",K19/I19) | M19: =IF(OR(I19="",N(E19)=0),"",I19/E19) | N19: =IF(I19="","",MAX(0,K19)) | O19: =IF(I19="","",MAX(0,K19*Paramètres!$B$11)) | P19: =IF(I19="","",IF(K19<=0,"Vente à perte",IF(AND(M19<>"",M19<2),"Marge faible (< x2)","Marge saine"))) | S19: =IF(B19="","",SUMIFS(Ventes!$G$6:$G$505,Ventes!$F$6:$F$505,B19,Ventes!$M$6:$M$505,"Livrée et payée")) | T19: =IF(OR(B19="",C19="Service"),"",N(Q19)+N(R19)-N(S19)) | V19: =IF(OR(B19="",C19="Service",Q19=""),"",IF(T19<=N(U19),"Réapprovisionner","OK"))
J20: =IF(I20="","",N(E20)+N(F20)+N(G20)+N(H20)) | K20: =IF(I20="","",I20-J20) | L20: =IF(OR(I20="",N(I20)=0),"",K20/I20) | M20: =IF(OR(I20="",N(E20)=0),"",I20/E20) | N20: =IF(I20="","",MAX(0,K20)) | O20: =IF(I20="","",MAX(0,K20*Paramètres!$B$11)) | P20: =IF(I20="","",IF(K20<=0,"Vente à perte",IF(AND(M20<>"",M20<2),"Marge faible (< x2)","Marge saine"))) | S20: =IF(B20="","",SUMIFS(Ventes!$G$6:$G$505,Ventes!$F$6:$F$505,B20,Ventes!$M$6:$M$505,"Livrée et payée")) | T20: =IF(OR(B20="",C20="Service"),"",N(Q20)+N(R20)-N(S20)) | V20: =IF(OR(B20="",C20="Service",Q20=""),"",IF(T20<=N(U20),"Réapprovisionner","OK"))
J21: =IF(I21="","",N(E21)+N(F21)+N(G21)+N(H21)) | K21: =IF(I21="","",I21-J21) | L21: =IF(OR(I21="",N(I21)=0),"",K21/I21) | M21: =IF(OR(I21="",N(E21)=0),"",I21/E21) | N21: =IF(I21="","",MAX(0,K21)) | O21: =IF(I21="","",MAX(0,K21*Paramètres!$B$11)) | P21: =IF(I21="","",IF(K21<=0,"Vente à perte",IF(AND(M21<>"",M21<2),"Marge faible (< x2)","Marge saine"))) | S21: =IF(B21="","",SUMIFS(Ventes!$G$6:$G$505,Ventes!$F$6:$F$505,B21,Ventes!$M$6:$M$505,"Livrée et payée")) | T21: =IF(OR(B21="",C21="Service"),"",N(Q21)+N(R21)-N(S21)) | V21: =IF(OR(B21="",C21="Service",Q21=""),"",IF(T21<=N(U21),"Réapprovisionner","OK"))
... J55: =IF(I55="","",N(E55)+N(F55)+N(G55)+N(H55)) | K55: =IF(I55="","",I55-J55) | L55: =IF(OR(I55="",N(I55)=0),"",K55/I55) | M55: =IF(OR(I55="",N(E55)=0),"",I55/E55) | N55: =IF(I55="","",MAX(0,K55)) | O55: =IF(I55="","",MAX(0,K55*Paramètres!$B$11)) | P55: =IF(I55="","",IF(K55<=0,"Vente à perte",IF(AND(M55<>"",M55<2),"Marge faible (< x2)","Marge saine"))) | S55: =IF(B55="","",SUMIFS(Ventes!$G$6:$G$505,Ventes!$F$6:$F$505,B55,Ventes!$M$6:$M$505,"Livrée et payée")) | T55: =IF(OR(B55="",C55="Service"),"",N(Q55)+N(R55)-N(S55)) | V55: =IF(OR(B55="",C55="Service",Q55=""),"",IF(T55<=N(U55),"Réapprovisionner","OK"))

Sheet Grille produit
A1: Grille produit : ce produit va-t-il se vendre ?
A2: Note chaque critère de 0 à 2. Garde les produits qui font 9 ou plus sur 12, puis fais une publication test (chapitre 2).
A3: Cellules jaunes : à remplir · cellules grises : calculées automatiquement (ne pas modifier)
A5: Produit envisagé | B5: Règle un problème ou un désir fort | C5: Marge d’au moins x2 | D5: Facile à livrer | E5: Se montre bien en vidéo | F5: Pas disponible partout au même prix | G5: Donne envie de racheter | H5: Total / 12 | I5: Décision | J5: Messages reçus (publication test) | K5: Verdict du test
A6: Pagne wax 6 yards | B6: 2 | C6: 2 | D6: 2 | E6: 2 | F6: 1 | G6: 2 | H6: =IF(A6="","",SUM(B6:G6)) -> 11 | I6: =IF(A6="","",IF(H6>=9,"À tester",IF(H6>=7,"À retravailler","Écarter"))) -> À tester | J6: 12 | K6: =IF(OR(A6="",J6=""),"",IF(J6>=10,"Commander un petit stock","Changer d’angle, de photo ou de produit")) -> Commander un petit stock
A7: Montre connectée | B7: 1 | C7: 1 | D7: 2 | E7: 2 | F7: 0 | G7: 0 | H7: =IF(A7="","",SUM(B7:G7)) -> 6 | I7: =IF(A7="","",IF(H7>=9,"À tester",IF(H7>=7,"À retravailler","Écarter"))) -> Écarter | J7: 3 | K7: =IF(OR(A7="",J7=""),"",IF(J7>=10,"Commander un petit stock","Changer d’angle, de photo ou de produit")) -> Changer d’angle, de photo ou de produit
H8: =IF(A8="","",SUM(B8:G8)) | I8: =IF(A8="","",IF(H8>=9,"À tester",IF(H8>=7,"À retravailler","Écarter"))) | K8: =IF(OR(A8="",J8=""),"",IF(J8>=10,"Commander un petit stock","Changer d’angle, de photo ou de produit"))
H9: =IF(A9="","",SUM(B9:G9)) | I9: =IF(A9="","",IF(H9>=9,"À tester",IF(H9>=7,"À retravailler","Écarter"))) | K9: =IF(OR(A9="",J9=""),"",IF(J9>=10,"Commander un petit stock","Changer d’angle, de photo ou de produit"))
H10: =IF(A10="","",SUM(B10:G10)) | I10: =IF(A10="","",IF(H10>=9,"À tester",IF(H10>=7,"À retravailler","Écarter"))) | K10: =IF(OR(A10="",J10=""),"",IF(J10>=10,"Commander un petit stock","Changer d’angle, de photo ou de produit"))
H11: =IF(A11="","",SUM(B11:G11)) | I11: =IF(A11="","",IF(H11>=9,"À tester",IF(H11>=7,"À retravailler","Écarter"))) | K11: =IF(OR(A11="",J11=""),"",IF(J11>=10,"Commander un petit stock","Changer d’angle, de photo ou de produit"))
H12: =IF(A12="","",SUM(B12:G12)) | I12: =IF(A12="","",IF(H12>=9,"À tester",IF(H12>=7,"À retravailler","Écarter"))) | K12: =IF(OR(A12="",J12=""),"",IF(J12>=10,"Commander un petit stock","Changer d’angle, de photo ou de produit"))
H13: =IF(A13="","",SUM(B13:G13)) | I13: =IF(A13="","",IF(H13>=9,"À tester",IF(H13>=7,"À retravailler","Écarter"))) | K13: =IF(OR(A13="",J13=""),"",IF(J13>=10,"Commander un petit stock","Changer d’angle, de photo ou de produit"))
H14: =IF(A14="","",SUM(B14:G14)) | I14: =IF(A14="","",IF(H14>=9,"À tester",IF(H14>=7,"À retravailler","Écarter"))) | K14: =IF(OR(A14="",J14=""),"",IF(J14>=10,"Commander un petit stock","Changer d’angle, de photo ou de produit"))
H15: =IF(A15="","",SUM(B15:G15)) | I15: =IF(A15="","",IF(H15>=9,"À tester",IF(H15>=7,"À retravailler","Écarter"))) | K15: =IF(OR(A15="",J15=""),"",IF(J15>=10,"Commander un petit stock","Changer d’angle, de photo ou de produit"))
H16: =IF(A16="","",SUM(B16:G16)) | I16: =IF(A16="","",IF(H16>=9,"À tester",IF(H16>=7,"À retravailler","Écarter"))) | K16: =IF(OR(A16="",J16=""),"",IF(J16>=10,"Commander un petit stock","Changer d’angle, de photo ou de produit"))
H17: =IF(A17="","",SUM(B17:G17)) | I17: =IF(A17="","",IF(H17>=9,"À tester",IF(H17>=7,"À retravailler","Écarter"))) | K17: =IF(OR(A17="",J17=""),"",IF(J17>=10,"Commander un petit stock","Changer d’angle, de photo ou de produit"))
H18: =IF(A18="","",SUM(B18:G18)) | I18: =IF(A18="","",IF(H18>=9,"À tester",IF(H18>=7,"À retravailler","Écarter"))) | K18: =IF(OR(A18="",J18=""),"",IF(J18>=10,"Commander un petit stock","Changer d’angle, de photo ou de produit"))
H19: =IF(A19="","",SUM(B19:G19)) | I19: =IF(A19="","",IF(H19>=9,"À tester",IF(H19>=7,"À retravailler","Écarter"))) | K19: =IF(OR(A19="",J19=""),"",IF(J19>=10,"Commander un petit stock","Changer d’angle, de photo ou de produit"))
H20: =IF(A20="","",SUM(B20:G20)) | I20: =IF(A20="","",IF(H20>=9,"À tester",IF(H20>=7,"À retravailler","Écarter"))) | K20: =IF(OR(A20="",J20=""),"",IF(J20>=10,"Commander un petit stock","Changer d’angle, de photo ou de produit"))
A22: Règle du livre : une publication test qui génère au moins 10 messages sérieux justifie un petit stock. Sinon, change d’angle, de photo ou de produit.

Sheet Calcul marge
A1: Simulateur : vraie marge et rentabilité d’une pub
A2: Prérempli avec l’exemple du livre : remplace les cellules jaunes par tes chiffres.
A3: Cellules jaunes : à remplir · cellules grises : calculées automatiquement (ne pas modifier)
A5: 1. LE VRAI BÉNÉFICE PAR VENTE | D5: 2. CETTE PUB EST-ELLE RENTABLE ?
A6: Prix d’achat du produit (ou coût de revient du service) | B6: 4000 | D6: Budget dépensé (FCFA) | E6: 9000
A7: Emballage | B7: 200 | D7: Messages reçus | E7: 36
A8: Livraison payée par toi (si offerte) | B8: 1500 | D8: Ventes conclues | E8: 9
A9: Coût de pub moyen par vente | B9: 1000 | D9: Marge avant pub du produit | E9: =B14 -> 4200
A10: Frais de transfert ou divers | B10: 100 | D10: Coût par message | E10: =IF(E7=0,0,E6/E7) -> 250
A11: Prix de vente | B11: 10000 | D11: Taux de conversion | E11: =IF(E7=0,0,E8/E7) -> 0.25
A12: Coût total par vente | B12: =B6+B7+B8+B9+B10 -> 6800 | D12: Coût par vente | E12: =IF(E8=0,0,E6/E8) -> 1000
A13: Bénéfice réel par vente | B13: =B11-B12 -> 3200 | D13: Bénéfice par vente après pub | E13: =IF(E8=0,0,E9-E12) -> 3200
A14: Marge avant pub (plafond de pub par vente) | B14: =B11-(B6+B7+B8+B10) -> 4200 | D14: Bénéfice total de la pub | E14: =E8*E9-E6 -> 28800
A15: Seuil « augmenter » (coût par vente maximum) | B15: =B14*Paramètres!$B$11 -> 1400 | D15: Décision | E15: =IF(E8=0,IF(E6>=E9,"Couper","Attendre ou améliorer"),IF(E12<E9*Paramètres!$B$11,"Augmenter le budget de 20 à 30 %",IF(E12<=E9,"Améliorer : accroche, vidéo, réponses","Couper : change d’angle ou de produit"))) -> Augmenter le budget de 20 à 30 %
A16: Taux de bénéfice réel | B16: =IF(B11=0,0,B13/B11) -> 0.32
A17: Prix minimum pour un coefficient x2 | B17: =2*B6 -> 8000
A18: Prix minimum pour un coefficient x3 | B18: =3*B6 -> 12000
A19: Verdict | B19: =IF(B13<=0,"Tu perds de l’argent : revois prix ou coûts",IF(B11<2*B6,"Marge faible : vise au moins x2","Prix sain")) -> Prix sain
A21: Exemple du livre : prix 10 000, coût total 6 800, bénéfice réel 3 200 FCFA ; pub : 9 000 FCFA, 36 messages, 9 ventes → 1 000 FCFA par vente, on augmente.

Sheet Suivi pubs
A1: Suivi quotidien des pubs
A2: Remplis chaque soir. Les ventes, c’est toi qui les notes : Facebook ne sait pas qui a payé sur WhatsApp.
A3: Cellules jaunes : à remplir · cellules grises : calculées automatiquement (ne pas modifier)
A5: Date | B5: Nom de la pub | C5: Produit / service | D5: Version | E5: Dépensé (FCFA) | F5: Messages | G5: Ventes | H5: Coût par message | I5: Taux de conversion | J5: Coût par vente | K5: Marge avant pub | L5: Bénéfice après pub | M5: Lecture du jour | N5: Mois
A6: 46301 | B6: Pub A · le problème | C6: Pagne wax 6 yards | D6: A | E6: 1500 | F6: 7 | G6: 1 | H6: =IF(N(F6)>0,E6/F6,"") -> 214.28571 | I6: =IF(N(F6)>0,G6/F6,"") -> 0.14285714 | J6: =IF(N(G6)>0,E6/G6,"") -> 1500 | K6: =IF(C6="","",IFERROR(INDEX(Catalogue!$K$6:$K$55,MATCH(C6,Catalogue!$B$6:$B$55,0)),"")) -> 4200 | L6: =IF(OR(E6="",K6=""),"",N(G6)*K6-E6) -> 2700 | M6: =IF(OR(E6="",K6=""),"",IF(N(G6)=0,"Pas de vente aujourd’hui",IF(J6<K6*Paramètres!$B$11,"Rentable",IF(J6<=K6,"Juste rentable","Perte")))) -> Juste rentable | N6: =IF(A6="","",DATE(YEAR(A6),MONTH(A6),1)) -> 46296
A7: 46302 | B7: Pub A · le problème | C7: Pagne wax 6 yards | D7: A | E7: 1500 | F7: 8 | G7: 1 | H7: =IF(N(F7)>0,E7/F7,"") -> 187.5 | I7: =IF(N(F7)>0,G7/F7,"") -> 0.125 | J7: =IF(N(G7)>0,E7/G7,"") -> 1500 | K7: =IF(C7="","",IFERROR(INDEX(Catalogue!$K$6:$K$55,MATCH(C7,Catalogue!$B$6:$B$55,0)),"")) -> 4200 | L7: =IF(OR(E7="",K7=""),"",N(G7)*K7-E7) -> 2700 | M7: =IF(OR(E7="",K7=""),"",IF(N(G7)=0,"Pas de vente aujourd’hui",IF(J7<K7*Paramètres!$B$11,"Rentable",IF(J7<=K7,"Juste rentable","Perte")))) -> Juste rentable | N7: =IF(A7="","",DATE(YEAR(A7),MONTH(A7),1)) -> 46296
A8: 46303 | B8: Pub A · le problème | C8: Pagne wax 6 yards | D8: A | E8: 1500 | F8: 6 | G8: 1 | H8: =IF(N(F8)>0,E8/F8,"") -> 250 | I8: =IF(N(F8)>0,G8/F8,"") -> 0.16666667 | J8: =IF(N(G8)>0,E8/G8,"") -> 1500 | K8: =IF(C8="","",IFERROR(INDEX(Catalogue!$K$6:$K$55,MATCH(C8,Catalogue!$B$6:$B$55,0)),"")) -> 4200 | L8: =IF(OR(E8="",K8=""),"",N(G8)*K8-E8) -> 2700 | M8: =IF(OR(E8="",K8=""),"",IF(N(G8)=0,"Pas de vente aujourd’hui",IF(J8<K8*Paramètres!$B$11,"Rentable",IF(J8<=K8,"Juste rentable","Perte")))) -> Juste rentable | N8: =IF(A8="","",DATE(YEAR(A8),MONTH(A8),1)) -> 46296
A9: 46304 | B9: Pub A · le problème | C9: Pagne wax 6 yards | D9: A | E9: 1500 | F9: 9 | G9: 2 | H9: =IF(N(F9)>0,E9/F9,"") -> 166.66667 | I9: =IF(N(F9)>0,G9/F9,"") -> 0.22222222 | J9: =IF(N(G9)>0,E9/G9,"") -> 750 | K9: =IF(C9="","",IFERROR(INDEX(Catalogue!$K$6:$K$55,MATCH(C9,Catalogue!$B$6:$B$55,0)),"")) -> 4200 | L9: =IF(OR(E9="",K9=""),"",N(G9)*K9-E9) -> 6900 | M9: =IF(OR(E9="",K9=""),"",IF(N(G9)=0,"Pas de vente aujourd’hui",IF(J9<K9*Paramètres!$B$11,"Rentable",IF(J9<=K9,"Juste rentable","Perte")))) -> Rentable | N9: =IF(A9="","",DATE(YEAR(A9),MONTH(A9),1)) -> 46296
A10: 46305 | B10: Pub A · le problème | C10: Pagne wax 6 yards | D10: A | E10: 1500 | F10: 7 | G10: 1 | H10: =IF(N(F10)>0,E10/F10,"") -> 214.28571 | I10: =IF(N(F10)>0,G10/F10,"") -> 0.14285714 | J10: =IF(N(G10)>0,E10/G10,"") -> 1500 | K10: =IF(C10="","",IFERROR(INDEX(Catalogue!$K$6:$K$55,MATCH(C10,Catalogue!$B$6:$B$55,0)),"")) -> 4200 | L10: =IF(OR(E10="",K10=""),"",N(G10)*K10-E10) -> 2700 | M10: =IF(OR(E10="",K10=""),"",IF(N(G10)=0,"Pas de vente aujourd’hui",IF(J10<K10*Paramètres!$B$11,"Rentable",IF(J10<=K10,"Juste rentable","Perte")))) -> Juste rentable | N10: =IF(A10="","",DATE(YEAR(A10),MONTH(A10),1)) -> 46296
A11: 46301 | B11: Pub B · témoignage | C11: Pagne wax 6 yards | D11: B | E11: 1500 | F11: 4 | G11: 0 | H11: =IF(N(F11)>0,E11/F11,"") -> 375 | I11: =IF(N(F11)>0,G11/F11,"") -> 0 | J11: =IF(N(G11)>0,E11/G11,"") | K11: =IF(C11="","",IFERROR(INDEX(Catalogue!$K$6:$K$55,MATCH(C11,Catalogue!$B$6:$B$55,0)),"")) -> 4200 | L11: =IF(OR(E11="",K11=""),"",N(G11)*K11-E11) -> -1500 | M11: =IF(OR(E11="",K11=""),"",IF(N(G11)=0,"Pas de vente aujourd’hui",IF(J11<K11*Paramètres!$B$11,"Rentable",IF(J11<=K11,"Juste rentable","Perte")))) -> Pas de vente aujourd’hui | N11: =IF(A11="","",DATE(YEAR(A11),MONTH(A11),1)) -> 46296
A12: 46302 | B12: Pub B · témoignage | C12: Pagne wax 6 yards | D12: B | E12: 1500 | F12: 3 | G12: 1 | H12: =IF(N(F12)>0,E12/F12,"") -> 500 | I12: =IF(N(F12)>0,G12/F12,"") -> 0.33333333 | J12: =IF(N(G12)>0,E12/G12,"") -> 1500 | K12: =IF(C12="","",IFERROR(INDEX(Catalogue!$K$6:$K$55,MATCH(C12,Catalogue!$B$6:$B$55,0)),"")) -> 4200 | L12: =IF(OR(E12="",K12=""),"",N(G12)*K12-E12) -> 2700 | M12: =IF(OR(E12="",K12=""),"",IF(N(G12)=0,"Pas de vente aujourd’hui",IF(J12<K12*Paramètres!$B$11,"Rentable",IF(J12<=K12,"Juste rentable","Perte")))) -> Juste rentable | N12: =IF(A12="","",DATE(YEAR(A12),MONTH(A12),1)) -> 46296
A13: 46303 | B13: Pub B · témoignage | C13: Pagne wax 6 yards | D13: B | E13: 1500 | F13: 5 | G13: 0 | H13: =IF(N(F13)>0,E13/F13,"") -> 300 | I13: =IF(N(F13)>0,G13/F13,"") -> 0 | J13: =IF(N(G13)>0,E13/G13,"") | K13: =IF(C13="","",IFERROR(INDEX(Catalogue!$K$6:$K$55,MATCH(C13,Catalogue!$B$6:$B$55,0)),"")) -> 4200 | L13: =IF(OR(E13="",K13=""),"",N(G13)*K13-E13) -> -1500 | M13: =IF(OR(E13="",K13=""),"",IF(N(G13)=0,"Pas de vente aujourd’hui",IF(J13<K13*Paramètres!$B$11,"Rentable",IF(J13<=K13,"Juste rentable","Perte")))) -> Pas de vente aujourd’hui | N13: =IF(A13="","",DATE(YEAR(A13),MONTH(A13),1)) -> 46296
A14: 46285 | B14: Pub test septembre | C14: Foulard assorti | D14: A | E14: 2000 | F14: 4 | G14: 1 | H14: =IF(N(F14)>0,E14/F14,"") -> 500 | I14: =IF(N(F14)>0,G14/F14,"") -> 0.25 | J14: =IF(N(G14)>0,E14/G14,"") -> 2000 | K14: =IF(C14="","",IFERROR(INDEX(Catalogue!$K$6:$K$55,MATCH(C14,Catalogue!$B$6:$B$55,0)),"")) -> 2150 | L14: =IF(OR(E14="",K14=""),"",N(G14)*K14-E14) -> 150 | M14: =IF(OR(E14="",K14=""),"",IF(N(G14)=0,"Pas de vente aujourd’hui",IF(J14<K14*Paramètres!$B$11,"Rentable",IF(J14<=K14,"Juste rentable","Perte")))) -> Juste rentable | N14: =IF(A14="","",DATE(YEAR(A14),MONTH(A14),1)) -> 46266
A15: 46286 | B15: Pub test septembre | C15: Foulard assorti | D15: A | E15: 2000 | F15: 3 | G15: 0 | H15: =IF(N(F15)>0,E15/F15,"") -> 666.66667 | I15: =IF(N(F15)>0,G15/F15,"") -> 0 | J15: =IF(N(G15)>0,E15/G15,"") | K15: =IF(C15="","",IFERROR(INDEX(Catalogue!$K$6:$K$55,MATCH(C15,Catalogue!$B$6:$B$55,0)),"")) -> 2150 | L15: =IF(OR(E15="",K15=""),"",N(G15)*K15-E15) -> -2000 | M15: =IF(OR(E15="",K15=""),"",IF(N(G15)=0,"Pas de vente aujourd’hui",IF(J15<K15*Paramètres!$B$11,"Rentable",IF(J15<=K15,"Juste rentable","Perte")))) -> Pas de vente aujourd’hui | N15: =IF(A15="","",DATE(YEAR(A15),MONTH(A15),1)) -> 46266
A16: 46287 | B16: Pub test septembre | C16: Foulard assorti | D16: A | E16: 2000 | F16: 5 | G16: 0 | H16: =IF(N(F16)>0,E16/F16,"") -> 400 | I16: =IF(N(F16)>0,G16/F16,"") -> 0 | J16: =IF(N(G16)>0,E16/G16,"") | K16: =IF(C16="","",IFERROR(INDEX(Catalogue!$K$6:$K$55,MATCH(C16,Catalogue!$B$6:$B$55,0)),"")) -> 2150 | L16: =IF(OR(E16="",K16=""),"",N(G16)*K16-E16) -> -2000 | M16: =IF(OR(E16="",K16=""),"",IF(N(G16)=0,"Pas de vente aujourd’hui",IF(J16<K16*Paramètres!$B$11,"Rentable",IF(J16<=K16,"Juste rentable","Perte")))) -> Pas de vente aujourd’hui | N16: =IF(A16="","",DATE(YEAR(A16),MONTH(A16),1)) -> 46266
H17: =IF(N(F17)>0,E17/F17,"") | I17: =IF(N(F17)>0,G17/F17,"") | J17: =IF(N(G17)>0,E17/G17,"") | K17: =IF(C17="","",IFERROR(INDEX(Catalogue!$K$6:$K$55,MATCH(C17,Catalogue!$B$6:$B$55,0)),"")) | L17: =IF(OR(E17="",K17=""),"",N(G17)*K17-E17) | M17: =IF(OR(E17="",K17=""),"",IF(N(G17)=0,"Pas de vente aujourd’hui",IF(J17<K17*Paramètres!$B$11,"Rentable",IF(J17<=K17,"Juste rentable","Perte")))) | N17: =IF(A17="","",DATE(YEAR(A17),MONTH(A17),1))
H18: =IF(N(F18)>0,E18/F18,"") | I18: =IF(N(F18)>0,G18/F18,"") | J18: =IF(N(G18)>0,E18/G18,"") | K18: =IF(C18="","",IFERROR(INDEX(Catalogue!$K$6:$K$55,MATCH(C18,Catalogue!$B$6:$B$55,0)),"")) | L18: =IF(OR(E18="",K18=""),"",N(G18)*K18-E18) | M18: =IF(OR(E18="",K18=""),"",IF(N(G18)=0,"Pas de vente aujourd’hui",IF(J18<K18*Paramètres!$B$11,"Rentable",IF(J18<=K18,"Juste rentable","Perte")))) | N18: =IF(A18="","",DATE(YEAR(A18),MONTH(A18),1))
H19: =IF(N(F19)>0,E19/F19,"") | I19: =IF(N(F19)>0,G19/F19,"") | J19: =IF(N(G19)>0,E19/G19,"") | K19: =IF(C19="","",IFERROR(INDEX(Catalogue!$K$6:$K$55,MATCH(C19,Catalogue!$B$6:$B$55,0)),"")) | L19: =IF(OR(E19="",K19=""),"",N(G19)*K19-E19) | M19: =IF(OR(E19="",K19=""),"",IF(N(G19)=0,"Pas de vente aujourd’hui",IF(J19<K19*Paramètres!$B$11,"Rentable",IF(J19<=K19,"Juste rentable","Perte")))) | N19: =IF(A19="","",DATE(YEAR(A19),MONTH(A19),1))
H20: =IF(N(F20)>0,E20/F20,"") | I20: =IF(N(F20)>0,G20/F20,"") | J20: =IF(N(G20)>0,E20/G20,"") | K20: =IF(C20="","",IFERROR(INDEX(Catalogue!$K$6:$K$55,MATCH(C20,Catalogue!$B$6:$B$55,0)),"")) | L20: =IF(OR(E20="",K20=""),"",N(G20)*K20-E20) | M20: =IF(OR(E20="",K20=""),"",IF(N(G20)=0,"Pas de vente aujourd’hui",IF(J20<K20*Paramètres!$B$11,"Rentable",IF(J20<=K20,"Juste rentable","Perte")))) | N20: =IF(A20="","",DATE(YEAR(A20),MONTH(A20),1))
H21: =IF(N(F21)>0,E21/F21,"") | I21: =IF(N(F21)>0,G21/F21,"") | J21: =IF(N(G21)>0,E21/G21,"") | K21: =IF(C21="","",IFERROR(INDEX(Catalogue!$K$6:$K$55,MATCH(C21,Catalogue!$B$6:$B$55,0)),"")) | L21: =IF(OR(E21="",K21=""),"",N(G21)*K21-E21) | M21: =IF(OR(E21="",K21=""),"",IF(N(G21)=0,"Pas de vente aujourd’hui",IF(J21<K21*Paramètres!$B$11,"Rentable",IF(J21<=K21,"Juste rentable","Perte")))) | N21: =IF(A21="","",DATE(YEAR(A21),MONTH(A21),1))
H22: =IF(N(F22)>0,E22/F22,"") | I22: =IF(N(F22)>0,G22/F22,"") | J22: =IF(N(G22)>0,E22/G22,"") | K22: =IF(C22="","",IFERROR(INDEX(Catalogue!$K$6:$K$55,MATCH(C22,Catalogue!$B$6:$B$55,0)),"")) | L22: =IF(OR(E22="",K22=""),"",N(G22)*K22-E22) | M22: =IF(OR(E22="",K22=""),"",IF(N(G22)=0,"Pas de vente aujourd’hui",IF(J22<K22*Paramètres!$B$11,"Rentable",IF(J22<=K22,"Juste rentable","Perte")))) | N22: =IF(A22="","",DATE(YEAR(A22),MONTH(A22),1))
H23: =IF(N(F23)>0,E23/F23,"") | I23: =IF(N(F23)>0,G23/F23,"") | J23: =IF(N(G23)>0,E23/G23,"") | K23: =IF(C23="","",IFERROR(INDEX(Catalogue!$K$6:$K$55,MATCH(C23,Catalogue!$B$6:$B$55,0)),"")) | L23: =IF(OR(E23="",K23=""),"",N(G23)*K23-E23) | M23: =IF(OR(E23="",K23=""),"",IF(N(G23)=0,"Pas de vente aujourd’hui",IF(J23<K23*Paramètres!$B$11,"Rentable",IF(J23<=K23,"Juste rentable","Perte")))) | N23: =IF(A23="","",DATE(YEAR(A23),MONTH(A23),1))
H24: =IF(N(F24)>0,E24/F24,"") | I24: =IF(N(F24)>0,G24/F24,"") | J24: =IF(N(G24)>0,E24/G24,"") | K24: =IF(C24="","",IFERROR(INDEX(Catalogue!$K$6:$K$55,MATCH(C24,Catalogue!$B$6:$B$55,0)),"")) | L24: =IF(OR(E24="",K24=""),"",N(G24)*K24-E24) | M24: =IF(OR(E24="",K24=""),"",IF(N(G24)=0,"Pas de vente aujourd’hui",IF(J24<K24*Paramètres!$B$11,"Rentable",IF(J24<=K24,"Juste rentable","Perte")))) | N24: =IF(A24="","",DATE(YEAR(A24),MONTH(A24),1))
H25: =IF(N(F25)>0,E25/F25,"") | I25: =IF(N(F25)>0,G25/F25,"") | J25: =IF(N(G25)>0,E25/G25,"") | K25: =IF(C25="","",IFERROR(INDEX(Catalogue!$K$6:$K$55,MATCH(C25,Catalogue!$B$6:$B$55,0)),"")) | L25: =IF(OR(E25="",K25=""),"",N(G25)*K25-E25) | M25: =IF(OR(E25="",K25=""),"",IF(N(G25)=0,"Pas de vente aujourd’hui",IF(J25<K25*Paramètres!$B$11,"Rentable",IF(J25<=K25,"Juste rentable","Perte")))) | N25: =IF(A25="","",DATE(YEAR(A25),MONTH(A25),1))
H26: =IF(N(F26)>0,E26/F26,"") | I26: =IF(N(F26)>0,G26/F26,"") | J26: =IF(N(G26)>0,E26/G26,"") | K26: =IF(C26="","",IFERROR(INDEX(Catalogue!$K$6:$K$55,MATCH(C26,Catalogue!$B$6:$B$55,0)),"")) | L26: =IF(OR(E26="",K26=""),"",N(G26)*K26-E26) | M26: =IF(OR(E26="",K26=""),"",IF(N(G26)=0,"Pas de vente aujourd’hui",IF(J26<K26*Paramètres!$B$11,"Rentable",IF(J26<=K26,"Juste rentable","Perte")))) | N26: =IF(A26="","",DATE(YEAR(A26),MONTH(A26),1))
H27: =IF(N(F27)>0,E27/F27,"") | I27: =IF(N(F27)>0,G27/F27,"") | J27: =IF(N(G27)>0,E27/G27,"") | K27: =IF(C27="","",IFERROR(INDEX(Catalogue!$K$6:$K$55,MATCH(C27,Catalogue!$B$6:$B$55,0)),"")) | L27: =IF(OR(E27="",K27=""),"",N(G27)*K27-E27) | M27: =IF(OR(E27="",K27=""),"",IF(N(G27)=0,"Pas de vente aujourd’hui",IF(J27<K27*Paramètres!$B$11,"Rentable",IF(J27<=K27,"Juste rentable","Perte")))) | N27: =IF(A27="","",DATE(YEAR(A27),MONTH(A27),1))
H28: =IF(N(F28)>0,E28/F28,"") | I28: =IF(N(F28)>0,G28/F28,"") | J28: =IF(N(G28)>0,E28/G28,"") | K28: =IF(C28="","",IFERROR(INDEX(Catalogue!$K$6:$K$55,MATCH(C28,Catalogue!$B$6:$B$55,0)),"")) | L28: =IF(OR(E28="",K28=""),"",N(G28)*K28-E28) | M28: =IF(OR(E28="",K28=""),"",IF(N(G28)=0,"Pas de vente aujourd’hui",IF(J28<K28*Paramètres!$B$11,"Rentable",IF(J28<=K28,"Juste rentable","Perte")))) | N28: =IF(A28="","",DATE(YEAR(A28),MONTH(A28),1))
... H370: =IF(N(F370)>0,E370/F370,"") | I370: =IF(N(F370)>0,G370/F370,"") | J370: =IF(N(G370)>0,E370/G370,"") | K370: =IF(C370="","",IFERROR(INDEX(Catalogue!$K$6:$K$55,MATCH(C370,Catalogue!$B$6:$B$55,0)),"")) | L370: =IF(OR(E370="",K370=""),"",N(G370)*K370-E370) | M370: =IF(OR(E370="",K370=""),"",IF(N(G370)=0,"Pas de vente aujourd’hui",IF(J370<K370*Paramètres!$B$11,"Rentable",IF(J370<=K370,"Juste rentable","Perte")))) | N370: =IF(A370="","",DATE(YEAR(A370),MONTH(A370),1))

Sheet Synthèse pubs
A1: Synthèse et décision par pub
A2: Écris le nom exact de chaque pub (comme dans Suivi pubs). La décision suit la règle du chapitre 8, après 3 à 4 jours.
A3: Cellules jaunes : à remplir · cellules grises : calculées automatiquement (ne pas modifier)
A5: Nom de la pub | B5: Produit / service | C5: Jours de diffusion | D5: Dépensé total | E5: Messages | F5: Ventes | G5: Coût par message | H5: Taux de conversion | I5: Coût par vente | J5: Marge avant pub | K5: Bénéfice total | L5: Décision | M5: Diagnostic
A6: Pub A · le problème | B6: =IF(A6="","",IFERROR(INDEX('Suivi pubs'!$C$6:$C$370,MATCH(A6,'Suivi pubs'!$B$6:$B$370,0)),"Nom introuvable")) -> Pagne wax 6 yards | C6: =IF(A6="","",COUNTIFS('Suivi pubs'!$B$6:$B$370,A6)) -> 5 | D6: =IF(A6="","",SUMIFS('Suivi pubs'!$E$6:$E$370,'Suivi pubs'!$B$6:$B$370,A6)) -> 7500 | E6: =IF(A6="","",SUMIFS('Suivi pubs'!$F$6:$F$370,'Suivi pubs'!$B$6:$B$370,A6)) -> 37 | F6: =IF(A6="","",SUMIFS('Suivi pubs'!$G$6:$G$370,'Suivi pubs'!$B$6:$B$370,A6)) -> 6 | G6: =IF(OR(A6="",N(E6)=0),"",D6/E6) -> 202.7027 | H6: =IF(OR(A6="",N(E6)=0),"",F6/E6) -> 0.16216216 | I6: =IF(OR(A6="",N(F6)=0),"",D6/F6) -> 1250 | J6: =IF(A6="","",IFERROR(INDEX(Catalogue!$K$6:$K$55,MATCH(B6,Catalogue!$B$6:$B$55,0)),"")) -> 4200 | K6: =IF(OR(A6="",J6=""),"",F6*J6-D6) -> 17700 | L6: =IF(OR(A6="",J6=""),"",IF(C6<Paramètres!$B$12,"Trop tôt : laisse tourner 3 à 4 jours",IF(F6=0,IF(D6>=J6,"Couper","Améliorer (aucune vente)"),IF(I6<J6*Paramètres!$B$11,"Augmenter (+20 à 30 %)",IF(I6<=J6,"Améliorer","Couper"))))) -> Augmenter (+20 à 30 %) | M6: =IF(OR(A6="",C6=0),"",IF(E6=0,"Pas de messages : revois l’accroche, le visuel ou le ciblage (chapitre 7)",IF(H6<Paramètres!$B$13,"Beaucoup de messages, peu de ventes : conversation, prix ou confiance (chapitre 9)","Conversion correcte : continue de tester de nouvelles versions"))) -> Conversion correcte : continue de tester de nouvelles versions
A7: Pub B · témoignage | B7: =IF(A7="","",IFERROR(INDEX('Suivi pubs'!$C$6:$C$370,MATCH(A7,'Suivi pubs'!$B$6:$B$370,0)),"Nom introuvable")) -> Pagne wax 6 yards | C7: =IF(A7="","",COUNTIFS('Suivi pubs'!$B$6:$B$370,A7)) -> 3 | D7: =IF(A7="","",SUMIFS('Suivi pubs'!$E$6:$E$370,'Suivi pubs'!$B$6:$B$370,A7)) -> 4500 | E7: =IF(A7="","",SUMIFS('Suivi pubs'!$F$6:$F$370,'Suivi pubs'!$B$6:$B$370,A7)) -> 12 | F7: =IF(A7="","",SUMIFS('Suivi pubs'!$G$6:$G$370,'Suivi pubs'!$B$6:$B$370,A7)) -> 1 | G7: =IF(OR(A7="",N(E7)=0),"",D7/E7) -> 375 | H7: =IF(OR(A7="",N(E7)=0),"",F7/E7) -> 0.083333333 | I7: =IF(OR(A7="",N(F7)=0),"",D7/F7) -> 4500 | J7: =IF(A7="","",IFERROR(INDEX(Catalogue!$K$6:$K$55,MATCH(B7,Catalogue!$B$6:$B$55,0)),"")) -> 4200 | K7: =IF(OR(A7="",J7=""),"",F7*J7-D7) -> -300 | L7: =IF(OR(A7="",J7=""),"",IF(C7<Paramètres!$B$12,"Trop tôt : laisse tourner 3 à 4 jours",IF(F7=0,IF(D7>=J7,"Couper","Améliorer (aucune vente)"),IF(I7<J7*Paramètres!$B$11,"Augmenter (+20 à 30 %)",IF(I7<=J7,"Améliorer","Couper"))))) -> Couper | M7: =IF(OR(A7="",C7=0),"",IF(E7=0,"Pas de messages : revois l’accroche, le visuel ou le ciblage (chapitre 7)",IF(H7<Paramètres!$B$13,"Beaucoup de messages, peu de ventes : conversation, prix ou confiance (chapitre 9)","Conversion correcte : continue de tester de nouvelles versions"))) -> Beaucoup de messages, peu de ventes : conversation, prix ou confiance (chapitre 9)
A8: Pub test septembre | B8: =IF(A8="","",IFERROR(INDEX('Suivi pubs'!$C$6:$C$370,MATCH(A8,'Suivi pubs'!$B$6:$B$370,0)),"Nom introuvable")) -> Foulard assorti | C8: =IF(A8="","",COUNTIFS('Suivi pubs'!$B$6:$B$370,A8)) -> 3 | D8: =IF(A8="","",SUMIFS('Suivi pubs'!$E$6:$E$370,'Suivi pubs'!$B$6:$B$370,A8)) -> 6000 | E8: =IF(A8="","",SUMIFS('Suivi pubs'!$F$6:$F$370,'Suivi pubs'!$B$6:$B$370,A8)) -> 12 | F8: =IF(A8="","",SUMIFS('Suivi pubs'!$G$6:$G$370,'Suivi pubs'!$B$6:$B$370,A8)) -> 1 | G8: =IF(OR(A8="",N(E8)=0),"",D8/E8) -> 500 | H8: =IF(OR(A8="",N(E8)=0),"",F8/E8) -> 0.083333333 | I8: =IF(OR(A8="",N(F8)=0),"",D8/F8) -> 6000 | J8: =IF(A8="","",IFERROR(INDEX(Catalogue!$K$6:$K$55,MATCH(B8,Catalogue!$B$6:$B$55,0)),"")) -> 2150 | K8: =IF(OR(A8="",J8=""),"",F8*J8-D8) -> -3850 | L8: =IF(OR(A8="",J8=""),"",IF(C8<Paramètres!$B$12,"Trop tôt : laisse tourner 3 à 4 jours",IF(F8=0,IF(D8>=J8,"Couper","Améliorer (aucune vente)"),IF(I8<J8*Paramètres!$B$11,"Augmenter (+20 à 30 %)",IF(I8<=J8,"Améliorer","Couper"))))) -> Couper | M8: =IF(OR(A8="",C8=0),"",IF(E8=0,"Pas de messages : revois l’accroche, le visuel ou le ciblage (chapitre 7)",IF(H8<Paramètres!$B$13,"Beaucoup de messages, peu de ventes : conversation, prix ou confiance (chapitre 9)","Conversion correcte : continue de tester de nouvelles versions"))) -> Beaucoup de messages, peu de ventes : conversation, prix ou confiance (chapitre 9)
